Workbook

Sheet 1-产品总表
A1: 1-产品总表
A2: 产品编码 | B2: 类目 | C2: 产品名称 | D2: 图片链接 | E2: SKU | F2: SKU编码 | G2: 上架状态 | H2: 产品文案介绍 | I2: 主材介绍 | J2: 辅材介绍 | K2: 尺寸明细 | L2: 定制范围 | M2: 备注 | N2: 导入校验 | O2: ⚠️问题标注
A3: PPS26330070320 | B3: 卧室-床 | C3: 畔色榉木无边床 |榉木金属腿床 | D3: https://img.alicdn.com/imgextra/i1/2215699812811/O1CN01weGhhJ1WdUTWXDll4_!!2215699812811.jpg | E3: 榉木无边床-1.2米-榉木铺板 | F3: PPS2633007032011 | G3: 在售 | H3: 德国进口AA级榉木：清新木色纹路。拒绝贴皮拒绝甲醛，安心呼吸整夜安睡。 10°床头舒适倾角：一体床架超静音。久靠也舒适，惬意倚靠感。 无边窄体设计：侧边无床沿。大幅拓宽床尾过道，更省空间。 超厚超密床铺板：承重强度MAX。抗弯曲防变形，保护床垫弹簧。 全床静音系统：龙骨静音贴处理。安心翻身无异响，助你好眠。 镜面不锈钢金属腿：0.1mm精度定制。科学力学结构，稳固承托更耐久。 床腿内收设计：避开踢脚线。轻盈不磕碰，床体贴合墙面。 预留透气孔：双排通风设计。防潮透气，床体会"呼吸"。 | I3: 德国进口AA级榉木 | J3: 床铺板：德国进口AA级榉木/新西兰松木；床腿；不锈钢 | K3: 宽度：1200mm；长度：2115mm；高度860 | L3: 床头高度可任意定制；床长度支持1800mm-2500mm定制；床宽度支持1000mm-2200mm定制；超出范围转人工 | M3: . | N3: ✅ 可导入 | O3: ✓
A4: PPS26330070320 | B4: 卧室-床 | C4: 畔色榉木无边床 |榉木金属腿床 | D4: https://img.alicdn.com/imgextra/i1/2215699812811/O1CN01weGhhJ1WdUTWXDll4_!!2215699812811.jpg | E4: 榉木无边床-1.35米-榉木铺板 | F4: PPS2633007032012 | G4: 在售 | H4: 德国进口AA级榉木：清新木色纹路。拒绝贴皮拒绝甲醛，安心呼吸整夜安睡。 10°床头舒适倾角：一体床架超静音。久靠也舒适，惬意倚靠感。 无边窄体设计：侧边无床沿。大幅拓宽床尾过道，更省空间。 超厚超密床铺板：承重强度MAX。抗弯曲防变形，保护床垫弹簧。 全床静音系统：龙骨静音贴处理。安心翻身无异响，助你好眠。 镜面不锈钢金属腿：0.1mm精度定制。科学力学结构，稳固承托更耐久。 床腿内收设计：避开踢脚线。轻盈不磕碰，床体贴合墙面。 预留透气孔：双排通风设计。防潮透气，床体会"呼吸"。 | I4: 德国进口AA级榉木 | J4: 床铺板：德国进口AA级榉木/新西兰松木；床腿；不锈钢 | K4: 宽度：1350mm；长度：2115mm；高度860 | L4: 床头高度可任意定制；床长度支持1800mm-2500mm定制；床宽度支持1000mm-2200mm定制；超出范围转人工 | M4: . | N4: ✅ 可导入 | O4: ✓
A5: PPS26330070320 | B5: 卧室-床 | C5: 畔色榉木无边床 |榉木金属腿床 | D5: https://img.alicdn.com/imgextra/i1/2215699812811/O1CN01weGhhJ1WdUTWXDll4_!!2215699812811.jpg | E5: 榉木无边床-1.5米-榉木铺板 | F5: PPS2633007032013 | G5: 在售 | H5: 德国进口AA级榉木：清新木色纹路。拒绝贴皮拒绝甲醛，安心呼吸整夜安睡。 10°床头舒适倾角：一体床架超静音。久靠也舒适，惬意倚靠感。 无边窄体设计：侧边无床沿。大幅拓宽床尾过道，更省空间。 超厚超密床铺板：承重强度MAX。抗弯曲防变形，保护床垫弹簧。 全床静音系统：龙骨静音贴处理。安心翻身无异响，助你好眠。 镜面不锈钢金属腿：0.1mm精度定制。科学力学结构，稳固承托更耐久。 床腿内收设计：避开踢脚线。轻盈不磕碰，床体贴合墙面。 预留透气孔：双排通风设计。防潮透气，床体会"呼吸"。 | I5: 德国进口AA级榉木 | J5: 床铺板：德国进口AA级榉木/新西兰松木；床腿；不锈钢 | K5: 宽度：1500mm；长度：2115mm；高度860 | L5: 床头高度可任意定制；床长度支持1800mm-2500mm定制；床宽度支持1000mm-2200mm定制；超出范围转人工 | M5: . | N5: ✅ 可导入 | O5: ✓
A6: PPS26330070320 | B6: 卧室-床 | C6: 畔色榉木无边床 |榉木金属腿床 | D6: https://img.alicdn.com/imgextra/i1/2215699812811/O1CN01weGhhJ1WdUTWXDll4_!!2215699812811.jpg | E6: 榉木无边床-1.8米-榉木铺板 | F6: PPS2633007032014 | G6: 在售 | H6: 德国进口AA级榉木：清新木色纹路。拒绝贴皮拒绝甲醛，安心呼吸整夜安睡。 10°床头舒适倾角：一体床架超静音。久靠也舒适，惬意倚靠感。 无边窄体设计：侧边无床沿。大幅拓宽床尾过道，更省空间。 超厚超密床铺板：承重强度MAX。抗弯曲防变形，保护床垫弹簧。 全床静音系统：龙骨静音贴处理。安心翻身无异响，助你好眠。 镜面不锈钢金属腿：0.1mm精度定制。科学力学结构，稳固承托更耐久。 床腿内收设计：避开踢脚线。轻盈不磕碰，床体贴合墙面。 预留透气孔：双排通风设计。防潮透气，床体会"呼吸"。 | I6: 德国进口AA级榉木 | J6: 床铺板：德国进口AA级榉木/新西兰松木；床腿；不锈钢 | K6: 宽度：1800mm；长度：2115mm；高度860 | L6: 床头高度可任意定制；床长度支持1800mm-2500mm定制；床宽度支持1000mm-2200mm定制；超出范围转人工 | N6: ✅ 可导入 | O6: ✓
A7: PPS26330070320 | B7: 卧室-床 | C7: 畔色榉木无边床 |榉木金属腿床 | D7: https://img.alicdn.com/imgextra/i1/2215699812811/O1CN01weGhhJ1WdUTWXDll4_!!2215699812811.jpg | E7: 榉木无边床-1.2米-松木铺板 | F7: PPS2633007032015 | G7: 在售 | H7: 德国进口AA级榉木：清新木色纹路。拒绝贴皮拒绝甲醛，安心呼吸整夜安睡。 10°床头舒适倾角：一体床架超静音。久靠也舒适，惬意倚靠感。 无边窄体设计：侧边无床沿。大幅拓宽床尾过道，更省空间。 超厚超密床铺板：承重强度MAX。抗弯曲防变形，保护床垫弹簧。 全床静音系统：龙骨静音贴处理。安心翻身无异响，助你好眠。 镜面不锈钢金属腿：0.1mm精度定制。科学力学结构，稳固承托更耐久。 床腿内收设计：避开踢脚线。轻盈不磕碰，床体贴合墙面。 预留透气孔：双排通风设计。防潮透气，床体会"呼吸"。 | I7: 德国进口AA级榉木 | J7: 床铺板：德国进口AA级榉木/新西兰松木；床腿；不锈钢 | K7: 宽度：1200mm；长度：2115mm；高度860 | L7: 床头高度可任意定制；床长度支持1800mm-2500mm定制；床宽度支持1000mm-2200mm定制；超出范围转人工 | M7: . | N7: ✅ 可导入 | O7: ✓
A8: PPS26330070320 | B8: 卧室-床 | C8: 畔色榉木无边床 |榉木金属腿床 | D8: https://img.alicdn.com/imgextra/i1/2215699812811/O1CN01weGhhJ1WdUTWXDll4_!!2215699812811.jpg | E8: 榉木无边床-1.35米-松木铺板 | F8: PPS2633007032016 | G8: 在售 | H8: 德国进口AA级榉木：清新木色纹路。拒绝贴皮拒绝甲醛，安心呼吸整夜安睡。 10°床头舒适倾角：一体床架超静音。久靠也舒适，惬意倚靠感。 无边窄体设计：侧边无床沿。大幅拓宽床尾过道，更省空间。 超厚超密床铺板：承重强度MAX。抗弯曲防变形，保护床垫弹簧。 全床静音系统：龙骨静音贴处理。安心翻身无异响，助你好眠。 镜面不锈钢金属腿：0.1mm精度定制。科学力学结构，稳固承托更耐久。 床腿内收设计：避开踢脚线。轻盈不磕碰，床体贴合墙面。 预留透气孔：双排通风设计。防潮透气，床体会"呼吸"。 | I8: 德国进口AA级榉木 | J8: 床铺板：德国进口AA级榉木/新西兰松木；床腿；不锈钢 | K8: 宽度：1350mm；长度：2115mm；高度860 | L8: 床头高度可任意定制；床长度支持1800mm-2500mm定制；床宽度支持1000mm-2200mm定制；超出范围转人工 | M8: . | N8: ✅ 可导入 | O8: ✓
A9: PPS26330070320 | B9: 卧室-床 | C9: 畔色榉木无边床 |榉木金属腿床 | D9: https://img.alicdn.com/imgextra/i1/2215699812811/O1CN01weGhhJ1WdUTWXDll4_!!2215699812811.jpg | E9: 榉木无边床-1.5米-松木铺板 | F9: PPS2633007032017 | G9: 在售 | H9: 德国进口AA级榉木：清新木色纹路。拒绝贴皮拒绝甲醛，安心呼吸整夜安睡。 10°床头舒适倾角：一体床架超静音。久靠也舒适，惬意倚靠感。 无边窄体设计：侧边无床沿。大幅拓宽床尾过道，更省空间。 超厚超密床铺板：承重强度MAX。抗弯曲防变形，保护床垫弹簧。 全床静音系统：龙骨静音贴处理。安心翻身无异响，助你好眠。 镜面不锈钢金属腿：0.1mm精度定制。科学力学结构，稳固承托更耐久。 床腿内收设计：避开踢脚线。轻盈不磕碰，床体贴合墙面。 预留透气孔：双排通风设计。防潮透气，床体会"呼吸"。 | I9: 德国进口AA级榉木 | J9: 床铺板：德国进口AA级榉木/新西兰松木；床腿；不锈钢 | K9: 宽度：1500mm；长度：2115mm；高度860 | L9: 床头高度可任意定制；床长度支持1800mm-2500mm定制；床宽度支持1000mm-2200mm定制；超出范围转人工 | M9: . | N9: ✅ 可导入 | O9: ✓
A10: PPS26330070320 | B10: 卧室-床 | C10: 畔色榉木无边床 |榉木金属腿床 | D10: https://img.alicdn.com/imgextra/i1/2215699812811/O1CN01weGhhJ1WdUTWXDll4_!!2215699812811.jpg | E10: 榉木无边床-1.8米-松木铺板 | F10: PPS2633007032018 | G10: 在售 | H10: 德国进口AA级榉木：清新木色纹路。拒绝贴皮拒绝甲醛，安心呼吸整夜安睡。 10°床头舒适倾角：一体床架超静音。久靠也舒适，惬意倚靠感。 无边窄体设计：侧边无床沿。大幅拓宽床尾过道，更省空间。 超厚超密床铺板：承重强度MAX。抗弯曲防变形，保护床垫弹簧。 全床静音系统：龙骨静音贴处理。安心翻身无异响，助你好眠。 镜面不锈钢金属腿：0.1mm精度定制。科学力学结构，稳固承托更耐久。 床腿内收设计：避开踢脚线。轻盈不磕碰，床体贴合墙面。 预留透气孔：双排通风设计。防潮透气，床体会"呼吸"。 | I10: 德国进口AA级榉木 | J10: 床铺板：德国进口AA级榉木/新西兰松木；床腿；不锈钢 | K10: 宽度：1800mm；长度：2115mm；高度860 | L10: 床头高度可任意定制；床长度支持1800mm-2500mm定制；床宽度支持1000mm-2200mm定制；超出范围转人工 | M10: . | N10: ✅ 可导入 | O10: ✓
A11: PPS26330080322 | B11: 卧室-床 | C11: 畔色榉木柔光双人床 |榉木小灯床 | D11: https://img.alicdn.com/imgextra/i3/2215699812811/O1CN011b8ljX1WdUTWEOKNH_!!2215699812811.jpg | E11: 榉木柔光床-1.2米-榉木铺板 | F11: PPS2633008032211 | G11: 在售 | H11: 德国进口AA级榉木：清新木色纹路。轻盈设计，自然和煦。 柔光磨砂床头灯：微光潺潺。细腻光线流淌，点亮美好夜晚。 悬浮空气感设计：让卧室清新自然。用光线勾勒美好形体。 薄床头设计：卧室空间节省10%。床尾走道宽松，更多收纳空间。 超高落地床头：从头到腰全方位舒适。大板直拼，舒畅木纹。 预设床头灯：轻按即亮。节省床头空间，无线开关位置随心。 360°床体倒圆：无惧磕碰。贴心友好，舒适亲肤。 床底挑空设计：扫地机清扫无忧。通风且清爽，方便打理。 | I11: 德国进口AA级榉木 | J11: 床铺板：德国进口AA级榉木/新西兰松木；床头灯：亚克力 | K11: 宽度：1250mm；长度：2100mm；高度880 | L11: 床头高度可任意定制；床长度支持1800mm-2500mm定制；床宽度支持1000mm-2200mm定制；超出范围转人工 | M11: . | N11: ✅ 可导入 | O11: ✓
A12: PPS26330080322 | B12: 卧室-床 | C12: 畔色榉木柔光双人床 |榉木小灯床 | D12: https://img.alicdn.com/imgextra/i3/2215699812811/O1CN011b8ljX1WdUTWEOKNH_!!2215699812811.jpg | E12: 榉木柔光床-1.35米-榉木铺板 | F12: PPS2633008032212 | G12: 在售 | H12: 德国进口AA级榉木：清新木色纹路。轻盈设计，自然和煦。 柔光磨砂床头灯：微光潺潺。细腻光线流淌，点亮美好夜晚。 悬浮空气感设计：让卧室清新自然。用光线勾勒美好形体。 薄床头设计：卧室空间节省10%。床尾走道宽松，更多收纳空间。 超高落地床头：从头到腰全方位舒适。大板直拼，舒畅木纹。 预设床头灯：轻按即亮。节省床头空间，无线开关位置随心。 360°床体倒圆：无惧磕碰。贴心友好，舒适亲肤。 床底挑空设计：扫地机清扫无忧。通风且清爽，方便打理。 | I12: 德国进口AA级榉木 | J12: 床铺板：德国进口AA级榉木/新西兰松木；床头灯：亚克力 | K12: 宽度：1400mm；长度：2100mm；高度880 | L12: 床头高度可任意定制；床长度支持1800mm-2500mm定制；床宽度支持1000mm-2200mm定制；超出范围转人工 | M12: . | N12: ✅ 可导入 | O12: ✓
A13: PPS26330080322 | B13: 卧室-床 | C13: 畔色榉木柔光双人床 |榉木小灯床 | D13: https://img.alicdn.com/imgextra/i3/2215699812811/O1CN011b8ljX1WdUTWEOKNH_!!2215699812811.jpg | E13: 榉木柔光床-1.5米-榉木铺板 | F13: PPS2633008032213 | G13: 在售 | H13: 德国进口AA级榉木：清新木色纹路。轻盈设计，自然和煦。 柔光磨砂床头灯：微光潺潺。细腻光线流淌，点亮美好夜晚。 悬浮空气感设计：让卧室清新自然。用光线勾勒美好形体。 薄床头设计：卧室空间节省10%。床尾走道宽松，更多收纳空间。 超高落地床头：从头到腰全方位舒适。大板直拼，舒畅木纹。 预设床头灯：轻按即亮。节省床头空间，无线开关位置随心。 360°床体倒圆：无惧磕碰。贴心友好，舒适亲肤。 床底挑空设计：扫地机清扫无忧。通风且清爽，方便打理。 | I13: 德国进口AA级榉木 | J13: 床铺板：德国进口AA级榉木/新西兰松木；床头灯：亚克力 | K13: 宽度：1550mm；长度：2100mm；高度880 | L13: 床头高度可任意定制；床长度支持1800mm-2500mm定制；床宽度支持1000mm-2200mm定制；超出范围转人工 | M13: . | N13: ✅ 可导入 | O13: ✓
A14: PPS26330080322 | B14: 卧室-床 | C14: 畔色榉木柔光双人床 |榉木小灯床 | D14: https://img.alicdn.com/imgextra/i3/2215699812811/O1CN011b8ljX1WdUTWEOKNH_!!2215699812811.jpg | E14: 榉木柔光床-1.8米-榉木铺板 | F14: PPS2633008032214 | G14: 在售 | H14: 德国进口AA级榉木：清新木色纹路。轻盈设计，自然和煦。 柔光磨砂床头灯：微光潺潺。细腻光线流淌，点亮美好夜晚。 悬浮空气感设计：让卧室清新自然。用光线勾勒美好形体。 薄床头设计：卧室空间节省10%。床尾走道宽松，更多收纳空间。 超高落地床头：从头到腰全方位舒适。大板直拼，舒畅木纹。 预设床头灯：轻按即亮。节省床头空间，无线开关位置随心。 360°床体倒圆：无惧磕碰。贴心友好，舒适亲肤。 床底挑空设计：扫地机清扫无忧。通风且清爽，方便打理。 | I14: 德国进口AA级榉木 | J14: 床铺板：德国进口AA级榉木/新西兰松木；床头灯：亚克力 | K14: 宽度：1850mm；长度：2100mm；高度880 | L14: 床头高度可任意定制；床长度支持1800mm-2500mm定制；床宽度支持1000mm-2200mm定制；超出范围转人工 | M14: . | N14: ✅ 可导入 | O14: ✓
A15: PPS26330080322 | B15: 卧室-床 | C15: 畔色榉木柔光双人床 |榉木小灯床 | D15: https://img.alicdn.com/imgextra/i3/2215699812811/O1CN011b8ljX1WdUTWEOKNH_!!2215699812811.jpg | E15: 榉木柔光床-1.2米-松木铺板 | F15: PPS2633008032215 | G15: 在售 | H15: 德国进口AA级榉木：清新木色纹路。轻盈设计，自然和煦。 柔光磨砂床头灯：微光潺潺。细腻光线流淌，点亮美好夜晚。 悬浮空气感设计：让卧室清新自然。用光线勾勒美好形体。 薄床头设计：卧室空间节省10%。床尾走道宽松，更多收纳空间。 超高落地床头：从头到腰全方位舒适。大板直拼，舒畅木纹。 预设床头灯：轻按即亮。节省床头空间，无线开关位置随心。 360°床体倒圆：无惧磕碰。贴心友好，舒适亲肤。 床底挑空设计：扫地机清扫无忧。通风且清爽，方便打理。 | I15: 德国进口AA级榉木 | J15: 床铺板：德国进口AA级榉木/新西兰松木；床头灯：亚克力 | K15: 宽度：1250mm；长度：2100mm；高度880 | L15: 床头高度可任意定制；床长度支持1800mm-2500mm定制；床宽度支持1000mm-2200mm定制；超出范围转人工 | M15: . | N15: ✅ 可导入 | O15: ✓
A16: PPS26330080322 | B16: 卧室-床 | C16: 畔色榉木柔光双人床 |榉木小灯床 | D16: https://img.alicdn.com/imgextra/i3/2215699812811/O1CN011b8ljX1WdUTWEOKNH_!!2215699812811.jpg | E16: 榉木柔光床-1.35米-松木铺板 | F16: PPS2633008032216 | G16: 在售 | H16: 德国进口AA级榉木：清新木色纹路。轻盈设计，自然和煦。 柔光磨砂床头灯：微光潺潺。细腻光线流淌，点亮美好夜晚。 悬浮空气感设计：让卧室清新自然。用光线勾勒美好形体。 薄床头设计：卧室空间节省10%。床尾走道宽松，更多收纳空间。 超高落地床头：从头到腰全方位舒适。大板直拼，舒畅木纹。 预设床头灯：轻按即亮。节省床头空间，无线开关位置随心。 360°床体倒圆：无惧磕碰。贴心友好，舒适亲肤。 床底挑空设计：扫地机清扫无忧。通风且清爽，方便打理。 | I16: 德国进口AA级榉木 | J16: 床铺板：德国进口AA级榉木/新西兰松木；床头灯：亚克力 | K16: 宽度：1400mm；长度：2100mm；高度880 | L16: 床头高度可任意定制；床长度支持1800mm-2500mm定制；床宽度支持1000mm-2200mm定制；超出范围转人工 | M16: . | N16: ✅ 可导入 | O16: ✓
A17: PPS26330080322 | B17: 卧室-床 | C17: 畔色榉木柔光双人床 |榉木小灯床 | D17: https://img.alicdn.com/imgextra/i3/2215699812811/O1CN011b8ljX1WdUTWEOKNH_!!2215699812811.jpg | E17: 榉木柔光床-1.5米-松木铺板 | F17: PPS2633008032217 | G17: 在售 | H17: 德国进口AA级榉木：清新木色纹路。轻盈设计，自然和煦。 柔光磨砂床头灯：微光潺潺。细腻光线流淌，点亮美好夜晚。 悬浮空气感设计：让卧室清新自然。用光线勾勒美好形体。 薄床头设计：卧室空间节省10%。床尾走道宽松，更多收纳空间。 超高落地床头：从头到腰全方位舒适。大板直拼，舒畅木纹。 预设床头灯：轻按即亮。节省床头空间，无线开关位置随心。 360°床体倒圆：无惧磕碰。贴心友好，舒适亲肤。 床底挑空设计：扫地机清扫无忧。通风且清爽，方便打理。 | I17: 德国进口AA级榉木 | J17: 床铺板：德国进口AA级榉木/新西兰松木；床头灯：亚克力 | K17: 宽度：1550mm；长度：2100mm；高度880 | L17: 床头高度可任意定制；床长度支持1800mm-2500mm定制；床宽度支持1000mm-2200mm定制；超出范围转人工 | M17: . | N17: ✅ 可导入 | O17: ✓
A18: PPS26330080322 | B18: 卧室-床 | C18: 畔色榉木柔光双人床 |榉木小灯床 | D18: https://img.alicdn.com/imgextra/i3/2215699812811/O1CN011b8ljX1WdUTWEOKNH_!!2215699812811.jpg | E18: 榉木柔光床-1.8米-松木铺板 | F18: PPS2633008032218 | G18: 在售 | H18: 德国进口AA级榉木：清新木色纹路。轻盈设计，自然和煦。 柔光磨砂床头灯：微光潺潺。细腻光线流淌，点亮美好夜晚。 悬浮空气感设计：让卧室清新自然。用光线勾勒美好形体。 薄床头设计：卧室空间节省10%。床尾走道宽松，更多收纳空间。 超高落地床头：从头到腰全方位舒适。大板直拼，舒畅木纹。 预设床头灯：轻按即亮。节省床头空间，无线开关位置随心。 360°床体倒圆：无惧磕碰。贴心友好，舒适亲肤。 床底挑空设计：扫地机清扫无忧。通风且清爽，方便打理。 | I18: 德国进口AA级榉木 | J18: 床铺板：德国进口AA级榉木/新西兰松木；床头灯：亚克力 | K18: 宽度：1850mm；长度：2100mm；高度880 | L18: 床头高度可任意定制；床长度支持1800mm-2500mm定制；床宽度支持1000mm-2200mm定制；超出范围转人工 | M18: . | N18: ✅ 可导入 | O18: ✓
... A71: PPS26330140117 | B71: 卧室-床 | C71: 畔色黑胡桃木软包双人床 |黑胡桃木落地大软包床 | D71: https://img.alicdn.com/imgextra/i4/2215699812811/O1CN01eDD7Xt1WdUTbnanUa_!!2215699812811.jpg | E71: 黑胡桃木软包床-1.8米-松木铺板 | F71: PPS2633014011718 | G71: 在售 | H71: 北美进口FAS级黑胡桃木：沙发级缓释靠包。重磅用料，SPA级舒睡体验。 丰满灯芯绒面料：温柔厚重抚触感。厚重舒适耐磨抗皱，可机洗。 沙发级填充结构：云般包裹体验。饱满充盈倚靠感，5A级鹅绒。 超高靠背：从腰部到颈部多点支撑。提供多层次缓释支撑。 建筑式块状承托腿：沉稳厚重倍支撑力。全床均匀受力，长久使用不变形。 悬浮感设计：释放卧室呼吸感。床下可储物，视觉通透。 平整车线工艺：线条利落有序。光线下的慵懒色泽，内敛贵族质感。 板式床腿内缩：日常行走不磕碰。全床圆润边角，舒适亲肤。 | I71: 北美进口FAS级黑胡桃木 | J71: 床铺板：德国进口AA级榉木/新西兰松木；床头软包：灯芯绒 | K71: 宽度：1890mm；长度：2270mm；高度880 | L71: 床头高度可任意定制；床长度支持1800mm-2500mm定制；床宽度支持1000mm-2200mm定制；超出范围转人工 | M71: . | N71: ✅ 可导入 | O71: ✓
A72: PPS26330140117 | B72: 卧室-床 | C72: 畔色黑胡桃木软包双人床 |黑胡桃木落地大软包床 | D72: https://img.alicdn.com/imgextra/i4/2215699812811/O1CN01eDD7Xt1WdUTbnanUa_!!2215699812811.jpg | E72: 黑胡桃木榻榻米（无床头）-1.2米-榉木铺板 | F72: PPS2633014011719 | G72: 在售 | H72: 北美进口FAS级黑胡桃木：沙发级缓释靠包。重磅用料，SPA级舒睡体验。 丰满灯芯绒面料：温柔厚重抚触感。厚重舒适耐磨抗皱，可机洗。 沙发级填充结构：云般包裹体验。饱满充盈倚靠感，5A级鹅绒。 超高靠背：从腰部到颈部多点支撑。提供多层次缓释支撑。 建筑式块状承托腿：沉稳厚重倍支撑力。全床均匀受力，长久使用不变形。 悬浮感设计：释放卧室呼吸感。床下可储物，视觉通透。 平整车线工艺：线条利落有序。光线下的慵懒色泽，内敛贵族质感。 板式床腿内缩：日常行走不磕碰。全床圆润边角，舒适亲肤。 | I72: 北美进口FAS级黑胡桃木 | J72: 床铺板：德国进口AA级榉木/新西兰松木；床头软包：灯芯绒 | K72: 宽度：1290mm；长度：2270mm；高度235 | L72: 床头高度可任意定制；床长度支持1800mm-2500mm定制；床宽度支持1000mm-2200mm定制；超出范围转人工 | N72: ✅ 可导入 | O72: ✓
A73: PPS26330140117 | B73: 卧室-床 | C73: 畔色黑胡桃木软包双人床 |黑胡桃木落地大软包床 | D73: https://img.alicdn.com/imgextra/i4/2215699812811/O1CN01eDD7Xt1WdUTbnanUa_!!2215699812811.jpg | E73: 黑胡桃木榻榻米（无床头）-1.35米-榉木铺板 | F73: PPS2633014011720 | G73: 在售 | H73: 北美进口FAS级黑胡桃木：沙发级缓释靠包。重磅用料，SPA级舒睡体验。 丰满灯芯绒面料：温柔厚重抚触感。厚重舒适耐磨抗皱，可机洗。 沙发级填充结构：云般包裹体验。饱满充盈倚靠感，5A级鹅绒。 超高靠背：从腰部到颈部多点支撑。提供多层次缓释支撑。 建筑式块状承托腿：沉稳厚重倍支撑力。全床均匀受力，长久使用不变形。 悬浮感设计：释放卧室呼吸感。床下可储物，视觉通透。 平整车线工艺：线条利落有序。光线下的慵懒色泽，内敛贵族质感。 板式床腿内缩：日常行走不磕碰。全床圆润边角，舒适亲肤。 | I73: 北美进口FAS级黑胡桃木 | J73: 床铺板：德国进口AA级榉木/新西兰松木；床头软包：灯芯绒 | K73: 宽度：1440mm；长度：2270mm；高度235 | L73: 床头高度可任意定制；床长度支持1800mm-2500mm定制；床宽度支持1000mm-2200mm定制；超出范围转人工 | N73: ✅ 可导入 | O73: ✓
A74: PPS26330140117 | B74: 卧室-床 | C74: 畔色黑胡桃木软包双人床 |黑胡桃木落地大软包床 | D74: https://img.alicdn.com/imgextra/i4/2215699812811/O1CN01eDD7Xt1WdUTbnanUa_!!2215699812811.jpg | E74: 黑胡桃木榻榻米（无床头）-1.5米-榉木铺板 | F74: PPS2633014011721 | G74: 在售 | H74: 北美进口FAS级黑胡桃木：沙发级缓释靠包。重磅用料，SPA级舒睡体验。 丰满灯芯绒面料：温柔厚重抚触感。厚重舒适耐磨抗皱，可机洗。 沙发级填充结构：云般包裹体验。饱满充盈倚靠感，5A级鹅绒。 超高靠背：从腰部到颈部多点支撑。提供多层次缓释支撑。 建筑式块状承托腿：沉稳厚重倍支撑力。全床均匀受力，长久使用不变形。 悬浮感设计：释放卧室呼吸感。床下可储物，视觉通透。 平整车线工艺：线条利落有序。光线下的慵懒色泽，内敛贵族质感。 板式床腿内缩：日常行走不磕碰。全床圆润边角，舒适亲肤。 | I74: 北美进口FAS级黑胡桃木 | J74: 床铺板：德国进口AA级榉木/新西兰松木；床头软包：灯芯绒 | K74: 宽度：1590mm；长度：2270mm；高度235 | L74: 床头高度可任意定制；床长度支持1800mm-2500mm定制；床宽度支持1000mm-2200mm定制；超出范围转人工 | N74: ✅ 可导入 | O74: ✓
A75: PPS26330140117 | B75: 卧室-床 | C75: 畔色黑胡桃木软包双人床 |黑胡桃木落地大软包床 | D75: https://img.alicdn.com/imgextra/i4/2215699812811/O1CN01eDD7Xt1WdUTbnanUa_!!2215699812811.jpg | E75: 黑胡桃木榻榻米（无床头）-1.8米-榉木铺板 | F75: PPS2633014011722 | G75: 在售 | H75: 北美进口FAS级黑胡桃木：沙发级缓释靠包。重磅用料，SPA级舒睡体验。 丰满灯芯绒面料：温柔厚重抚触感。厚重舒适耐磨抗皱，可机洗。 沙发级填充结构：云般包裹体验。饱满充盈倚靠感，5A级鹅绒。 超高靠背：从腰部到颈部多点支撑。提供多层次缓释支撑。 建筑式块状承托腿：沉稳厚重倍支撑力。全床均匀受力，长久使用不变形。 悬浮感设计：释放卧室呼吸感。床下可储物，视觉通透。 平整车线工艺：线条利落有序。光线下的慵懒色泽，内敛贵族质感。 板式床腿内缩：日常行走不磕碰。全床圆润边角，舒适亲肤。 | I75: 北美进口FAS级黑胡桃木 | J75: 床铺板：德国进口AA级榉木/新西兰松木；床头软包：灯芯绒 | K75: 宽度：1890mm；长度：2270mm；高度235 | L75: 床头高度可任意定制；床长度支持1800mm-2500mm定制；床宽度支持1000mm-2200mm定制；超出范围转人工 | N75: ✅ 可导入 | O75: ✓
A76: PPS26330150118 | B76: 卧室-床 | C76: 畔色黑胡桃木悬浮双人床 |黑胡桃木标准床 | D76: https://img.alicdn.com/imgextra/i4/2215699812811/O1CN015fCgsq1WdUTgF91sN_!!2215699812811.jpg | E76: 黑胡桃木悬浮床-1.2米-榉木铺板 | F76: PPS2633015011811 | G76: 在售 | H76: 暂无北美进口FAS级黑胡桃木：大板直拼流畅木纹。悬浮空气设计，云端睡卧感。 悬浮透光背板：点亮温馨夜晚。无线开关，无极亮暗调节。 床头预设电力插座：舒适不断线。床头背板可置物，兼具储物功能。 加厚圆墩象腿：强力稳固支撑。建筑式块状承托，沉稳厚重。 悬浮内收床腿：不磕碰。悬浮视感，放大卧室空间。 薄床头设计：卧室空间节省10%。窄体设计，床尾走道宽松。 超高落地床头：从头到腰的整体支撑。大板直拼舒畅木纹。 全床静音系统：安静安心。德国榉木双龙骨，10点支撑。 | I76: 北美进口FAS级黑胡桃木 | J76: 床铺板：德国进口AA级榉木/新西兰松木 | K76: 宽度：1250mm；长度：2100mm；高度950 | L76: 床头高度可任意定制；床长度支持1800mm-2500mm定制；床宽度支持1000mm-2200mm定制；超出范围转人工 | M76: . | N76: ✅ 可导入 | O76: ✓
A77: PPS26330150118 | B77: 卧室-床 | C77: 畔色黑胡桃木悬浮双人床 |黑胡桃木标准床 | D77: https://img.alicdn.com/imgextra/i4/2215699812811/O1CN015fCgsq1WdUTgF91sN_!!2215699812811.jpg | E77: 黑胡桃木悬浮床-1.35米-榉木铺板 | F77: PPS2633015011812 | G77: 在售 | H77: 暂无北美进口FAS级黑胡桃木：大板直拼流畅木纹。悬浮空气设计，云端睡卧感。 悬浮透光背板：点亮温馨夜晚。无线开关，无极亮暗调节。 床头预设电力插座：舒适不断线。床头背板可置物，兼具储物功能。 加厚圆墩象腿：强力稳固支撑。建筑式块状承托，沉稳厚重。 悬浮内收床腿：不磕碰。悬浮视感，放大卧室空间。 薄床头设计：卧室空间节省10%。窄体设计，床尾走道宽松。 超高落地床头：从头到腰的整体支撑。大板直拼舒畅木纹。 全床静音系统：安静安心。德国榉木双龙骨，10点支撑。 | I77: 北美进口FAS级黑胡桃木 | J77: 床铺板：德国进口AA级榉木/新西兰松木 | K77: 宽度：1400mm；长度：2100mm；高度950 | L77: 床头高度可任意定制；床长度支持1800mm-2500mm定制；床宽度支持1000mm-2200mm定制；超出范围转人工 | M77: . | N77: ✅ 可导入 | O77: ✓
A78: PPS26330150118 | B78: 卧室-床 | C78: 畔色黑胡桃木悬浮双人床 |黑胡桃木标准床 | D78: https://img.alicdn.com/imgextra/i4/2215699812811/O1CN015fCgsq1WdUTgF91sN_!!2215699812811.jpg | E78: 黑胡桃木悬浮床-1.5米-榉木铺板 | F78: PPS2633015011813 | G78: 在售 | H78: 暂无北美进口FAS级黑胡桃木：大板直拼流畅木纹。悬浮空气设计，云端睡卧感。 悬浮透光背板：点亮温馨夜晚。无线开关，无极亮暗调节。 床头预设电力插座：舒适不断线。床头背板可置物，兼具储物功能。 加厚圆墩象腿：强力稳固支撑。建筑式块状承托，沉稳厚重。 悬浮内收床腿：不磕碰。悬浮视感，放大卧室空间。 薄床头设计：卧室空间节省10%。窄体设计，床尾走道宽松。 超高落地床头：从头到腰的整体支撑。大板直拼舒畅木纹。 全床静音系统：安静安心。德国榉木双龙骨，10点支撑。 | I78: 北美进口FAS级黑胡桃木 | J78: 床铺板：德国进口AA级榉木/新西兰松木 | K78: 宽度：1550mm；长度：2100mm；高度950 | L78: 床头高度可任意定制；床长度支持1800mm-2500mm定制；床宽度支持1000mm-2200mm定制；超出范围转人工 | M78: . | N78: ✅ 可导入 | O78: ✓
A79: PPS26330150118 | B79: 卧室-床 | C79: 畔色黑胡桃木悬浮双人床 |黑胡桃木标准床 | D79: https://img.alicdn.com/imgextra/i4/2215699812811/O1CN015fCgsq1WdUTgF91sN_!!2215699812811.jpg | E79: 黑胡桃木悬浮床-1.8米-榉木铺板 | F79: PPS2633015011814 | G79: 在售 | H79: 暂无北美进口FAS级黑胡桃木：大板直拼流畅木纹。悬浮空气设计，云端睡卧感。 悬浮透光背板：点亮温馨夜晚。无线开关，无极亮暗调节。 床头预设电力插座：舒适不断线。床头背板可置物，兼具储物功能。 加厚圆墩象腿：强力稳固支撑。建筑式块状承托，沉稳厚重。 悬浮内收床腿：不磕碰。悬浮视感，放大卧室空间。 薄床头设计：卧室空间节省10%。窄体设计，床尾走道宽松。 超高落地床头：从头到腰的整体支撑。大板直拼舒畅木纹。 全床静音系统：安静安心。德国榉木双龙骨，10点支撑。 | I79: 北美进口FAS级黑胡桃木 | J79: 床铺板：德国进口AA级榉木/新西兰松木 | K79: 宽度：1850mm；长度：2100mm；高度950 | L79: 床头高度可任意定制；床长度支持1800mm-2500mm定制；床宽度支持1000mm-2200mm定制；超出范围转人工 | M79: . | N79: ✅ 可导入 | O79: ✓
A80: PPS26330150118 | B80: 卧室-床 | C80: 畔色黑胡桃木悬浮双人床 |黑胡桃木标准床 | D80: https://img.alicdn.com/imgextra/i4/2215699812811/O1CN015fCgsq1WdUTgF91sN_!!2215699812811.jpg | E80: 黑胡桃木悬浮床-1.2米-松木铺板 | F80: PPS2633015011815 | G80: 在售 | H80: 暂无北美进口FAS级黑胡桃木：大板直拼流畅木纹。悬浮空气设计，云端睡卧感。 悬浮透光背板：点亮温馨夜晚。无线开关，无极亮暗调节。 床头预设电力插座：舒适不断线。床头背板可置物，兼具储物功能。 加厚圆墩象腿：强力稳固支撑。建筑式块状承托，沉稳厚重。 悬浮内收床腿：不磕碰。悬浮视感，放大卧室空间。 薄床头设计：卧室空间节省10%。窄体设计，床尾走道宽松。 超高落地床头：从头到腰的整体支撑。大板直拼舒畅木纹。 全床静音系统：安静安心。德国榉木双龙骨，10点支撑。 | I80: 北美进口FAS级黑胡桃木 | J80: 床铺板：德国进口AA级榉木/新西兰松木 | K80: 宽度：1250mm；长度：2100mm；高度950 | L80: 床头高度可任意定制；床长度支持1800mm-2500mm定制；床宽度支持1000mm-2200mm定制；超出范围转人工 | M80: . | N80: ✅ 可导入 | O80: ✓
A81: PPS26330150118 | B81: 卧室-床 | C81: 畔色黑胡桃木悬浮双人床 |黑胡桃木标准床 | D81: https://img.alicdn.com/imgextra/i4/2215699812811/O1CN015fCgsq1WdUTgF91sN_!!2215699812811.jpg | E81: 黑胡桃木悬浮床-1.35米-松木铺板 | F81: PPS2633015011816 | G81: 在售 | H81: 暂无北美进口FAS级黑胡桃木：大板直拼流畅木纹。悬浮空气设计，云端睡卧感。 悬浮透光背板：点亮温馨夜晚。无线开关，无极亮暗调节。 床头预设电力插座：舒适不断线。床头背板可置物，兼具储物功能。 加厚圆墩象腿：强力稳固支撑。建筑式块状承托，沉稳厚重。 悬浮内收床腿：不磕碰。悬浮视感，放大卧室空间。 薄床头设计：卧室空间节省10%。窄体设计，床尾走道宽松。 超高落地床头：从头到腰的整体支撑。大板直拼舒畅木纹。 全床静音系统：安静安心。德国榉木双龙骨，10点支撑。 | I81: 北美进口FAS级黑胡桃木 | J81: 床铺板：德国进口AA级榉木/新西兰松木 | K81: 宽度：1400mm；长度：2100mm；高度950 | L81: 床头高度可任意定制；床长度支持1800mm-2500mm定制；床宽度支持1000mm-2200mm定制；超出范围转人工 | M81: . | N81: ✅ 可导入 | O81: ✓
A82: PPS26330150118 | B82: 卧室-床 | C82: 畔色黑胡桃木悬浮双人床 |黑胡桃木标准床 | D82: https://img.alicdn.com/imgextra/i4/2215699812811/O1CN015fCgsq1WdUTgF91sN_!!2215699812811.jpg | E82: 黑胡桃木悬浮床-1.5米-松木铺板 | F82: PPS2633015011817 | G82: 在售 | H82: 暂无北美进口FAS级黑胡桃木：大板直拼流畅木纹。悬浮空气设计，云端睡卧感。 悬浮透光背板：点亮温馨夜晚。无线开关，无极亮暗调节。 床头预设电力插座：舒适不断线。床头背板可置物，兼具储物功能。 加厚圆墩象腿：强力稳固支撑。建筑式块状承托，沉稳厚重。 悬浮内收床腿：不磕碰。悬浮视感，放大卧室空间。 薄床头设计：卧室空间节省10%。窄体设计，床尾走道宽松。 超高落地床头：从头到腰的整体支撑。大板直拼舒畅木纹。 全床静音系统：安静安心。德国榉木双龙骨，10点支撑。 | I82: 北美进口FAS级黑胡桃木 | J82: 床铺板：德国进口AA级榉木/新西兰松木 | K82: 宽度：1550mm；长度：2100mm；高度950 | L82: 床头高度可任意定制；床长度支持1800mm-2500mm定制；床宽度支持1000mm-2200mm定制；超出范围转人工 | M82: . | N82: ✅ 可导入 | O82: ✓
A83: PPS26330150118 | B83: 卧室-床 | C83: 畔色黑胡桃木悬浮双人床 |黑胡桃木标准床 | D83: https://img.alicdn.com/imgextra/i4/2215699812811/O1CN015fCgsq1WdUTgF91sN_!!2215699812811.jpg | E83: 黑胡桃木悬浮床-1.8米-松木铺板 | F83: PPS2633015011818 | G83: 在售 | H83: 暂无北美进口FAS级黑胡桃木：大板直拼流畅木纹。悬浮空气设计，云端睡卧感。 悬浮透光背板：点亮温馨夜晚。无线开关，无极亮暗调节。 床头预设电力插座：舒适不断线。床头背板可置物，兼具储物功能。 加厚圆墩象腿：强力稳固支撑。建筑式块状承托，沉稳厚重。 悬浮内收床腿：不磕碰。悬浮视感，放大卧室空间。 薄床头设计：卧室空间节省10%。窄体设计，床尾走道宽松。 超高落地床头：从头到腰的整体支撑。大板直拼舒畅木纹。 全床静音系统：安静安心。德国榉木双龙骨，10点支撑。 | I83: 北美进口FAS级黑胡桃木 | J83: 床铺板：德国进口AA级榉木/新西兰松木 | K83: 宽度：1850mm；长度：2100mm；高度950 | L83: 床头高度可任意定制；床长度支持1800mm-2500mm定制；床宽度支持1000mm-2200mm定制；超出范围转人工 | M83: . | N83: ✅ 可导入 | O83: ✓
A84: PPS26380040225 | B84: 卧室-床头柜 | C84: 畔色榉木床头柜 |榉木铁板床头柜 | D84: https://img.alicdn.com/imgextra/i1/2215699812811/O1CN01v4u1KN1WdUTcaGHb9_!!2215699812811.jpg | E84: 榉木床头柜-标准 | F84: PPS2638004022511 | G84: 在售 | H84: 德国进口AA级榉木：清新木色纹路。整柜原木拒绝贴皮，安心呼吸整夜安睡。 细腻美耐板台面：耐高温防指纹。脏污好清理，划痕可修复随心用。 宽窄双尺寸可选：灵活搭配各种空间。窄体设计留出卧室空间，衣柜开门顺畅。 边缘立耳设计：防止物件掉落。超宽置物台面，手机书籍安稳放置。 开放式收纳层：一目了然清爽抽板。不抽开也能拿，日用小物伸手可得。 大容量下抽：超大体积囤货无忧。书籍耳机纸巾面膜，分类收纳井井有条。 按压式抽屉面板：不弯腰也好开。随心开合方便自在，自吸静音底轨。 背板内收设计：轻松理线。后部走线孔，排插放置位预留。 柜体全落地：轻松免打扫。全柜圆润倒角，舒适亲肤磕碰无忧。 预留踢脚线位：方便贴墙。严丝合缝不藏垢，美观实用。 | I84: 德国进口AA级榉木 | K84: 长度：450mm 深度：400mm 高度：420mm | L84: 长度可任意定制；高度不可定制；深度不可定制 | M84: . | N84: ✅ 可导入 | O84: ✓
A85: PPS26380040225 | B85: 卧室-床头柜 | C85: 畔色榉木床头柜 |榉木铁板床头柜 | D85: https://img.alicdn.com/imgextra/i1/2215699812811/O1CN01v4u1KN1WdUTcaGHb9_!!2215699812811.jpg | E85: 榉木床头柜-窄款 | F85: PPS2638004022512 | G85: 在售 | H85: 德国进口AA级榉木：清新木色纹路。整柜原木拒绝贴皮，安心呼吸整夜安睡。 细腻美耐板台面：耐高温防指纹。脏污好清理，划痕可修复随心用。 宽窄双尺寸可选：灵活搭配各种空间。窄体设计留出卧室空间，衣柜开门顺畅。 边缘立耳设计：防止物件掉落。超宽置物台面，手机书籍安稳放置。 开放式收纳层：一目了然清爽抽板。不抽开也能拿，日用小物伸手可得。 大容量下抽：超大体积囤货无忧。书籍耳机纸巾面膜，分类收纳井井有条。 按压式抽屉面板：不弯腰也好开。随心开合方便自在，自吸静音底轨。 背板内收设计：轻松理线。后部走线孔，排插放置位预留。 柜体全落地：轻松免打扫。全柜圆润倒角，舒适亲肤磕碰无忧。 预留踢脚线位：方便贴墙。严丝合缝不藏垢，美观实用。 | I85: 德国进口AA级榉木 | K85: 长度：450mm 深度：400mm 高度：420mm | L85: 长度可任意定制；高度不可定制；深度不可定制 | M85: . | N85: ✅ 可导入 | O85: ✓
A86: PPS26380050301 | B86: 卧室-床头柜 | C86: 畔色樱桃木轻盈边柜 |樱桃木玻璃床头柜 |黑色玻璃床头柜 |樱桃木玻璃边柜 | D86: https://img.alicdn.com/imgextra/i4/2215699812811/O1CN01aV7b7w1WdUTd0Dctr_!!2215699812811.jpg | E86: 轻盈边柜-榉木黑-木底座 | F86: PPS2638005030111 | G86: 在售 | H86: 北美进口FAS级樱桃木：温润木色流畅纹路。整柜原木纹理细腻，自然和煦。 12mm超厚钢化玻璃台面：安全无虞。防冲击耐高温，晶莹透亮让光线自由呼吸。 长虹玻璃侧板：光影交织美学设计。空气感线条，光与影的浪漫在时刻中隽永驻留。 双层式置物设计：开放取物不拘束。躺着也好拿，日用小物伸手可得。 条块镂空底板：光线潺潺倾泻而下。分层收纳条理分明，插线板可隐藏轻松理线。 迷人夜灯：亮度无极可调。一键点亮光影艺术，潺潺微光静谧美梦相伴。 一体式钢化台面：清爽利落方便置物。台面玻璃倒圆，无惧磕碰亲肤好用。 侧边预留走线间隙：桌面更清爽。充电更便捷，告别杂乱线材。 背后预留踢脚线位：方便贴墙。高度刚刚好，随手放置很方便。 | I86: 德国进口AA级榉木 | J86: 侧板：玻璃 | K86: 长度：430mm 深度：510mm 高度：460mm | L86: 长度可任意定制；深度可任意定制；高度可任意定制； | M86: . | N86: ✅ 可导入 | O86: ✓
A87: PPS26380050301 | B87: 卧室-床头柜 | C87: 畔色樱桃木轻盈边柜 |樱桃木玻璃床头柜 |黑色玻璃床头柜 |樱桃木玻璃边柜 | D87: https://img.alicdn.com/imgextra/i4/2215699812811/O1CN01aV7b7w1WdUTd0Dctr_!!2215699812811.jpg | E87: 轻盈边柜-樱桃木-木底座 | F87: PPS2638005030112 | G87: 在售 | H87: 北美进口FAS级樱桃木：温润木色流畅纹路。整柜原木纹理细腻，自然和煦。 12mm超厚钢化玻璃台面：安全无虞。防冲击耐高温，晶莹透亮让光线自由呼吸。 长虹玻璃侧板：光影交织美学设计。空气感线条，光与影的浪漫在时刻中隽永驻留。 双层式置物设计：开放取物不拘束。躺着也好拿，日用小物伸手可得。 条块镂空底板：光线潺潺倾泻而下。分层收纳条理分明，插线板可隐藏轻松理线。 迷人夜灯：亮度无极可调。一键点亮光影艺术，潺潺微光静谧美梦相伴。 一体式钢化台面：清爽利落方便置物。台面玻璃倒圆，无惧磕碰亲肤好用。 侧边预留走线间隙：桌面更清爽。充电更便捷，告别杂乱线材。 背后预留踢脚线位：方便贴墙。高度刚刚好，随手放置很方便。 | I87: 北美进口FAS级樱桃木 | J87: 侧板：玻璃 | K87: 长度：430mm 深度：510mm 高度：460mm | L87: 长度可任意定制；深度可任意定制；高度可任意定制； | M87: . | N87: ✅ 可导入 | O87: ✓
A88: PPS26380050301 | B88: 卧室-床头柜 | C88: 畔色樱桃木轻盈边柜 |樱桃木玻璃床头柜 |黑色玻璃床头柜 |樱桃木玻璃边柜 | D88: https://img.alicdn.com/imgextra/i4/2215699812811/O1CN01aV7b7w1WdUTd0Dctr_!!2215699812811.jpg | E88: 轻盈边柜-黑胡桃木-木底座 | F88: PPS2638005030113 | G88: 在售 | H88: 北美进口FAS级樱桃木：温润木色流畅纹路。整柜原木纹理细腻，自然和煦。 12mm超厚钢化玻璃台面：安全无虞。防冲击耐高温，晶莹透亮让光线自由呼吸。 长虹玻璃侧板：光影交织美学设计。空气感线条，光与影的浪漫在时刻中隽永驻留。 双层式置物设计：开放取物不拘束。躺着也好拿，日用小物伸手可得。 条块镂空底板：光线潺潺倾泻而下。分层收纳条理分明，插线板可隐藏轻松理线。 迷人夜灯：亮度无极可调。一键点亮光影艺术，潺潺微光静谧美梦相伴。 一体式钢化台面：清爽利落方便置物。台面玻璃倒圆，无惧磕碰亲肤好用。 侧边预留走线间隙：桌面更清爽。充电更便捷，告别杂乱线材。 背后预留踢脚线位：方便贴墙。高度刚刚好，随手放置很方便。 | I88: 北美进口FAS级黑胡桃木 | J88: 侧板：玻璃 | K88: 长度：430mm 深度：510mm 高度：460mm | L88: 长度可任意定制；深度可任意定制；高度可任意定制； | M88: . | N88: ✅ 可导入 | O88: ✓
A89: PPS26380050301 | B89: 卧室-床头柜 | C89: 畔色樱桃木轻盈边柜 |樱桃木玻璃床头柜 |黑色玻璃床头柜 |樱桃木玻璃边柜 | D89: https://img.alicdn.com/imgextra/i4/2215699812811/O1CN01aV7b7w1WdUTd0Dctr_!!2215699812811.jpg | E89: 轻盈边柜-榉木黑-玻璃底座 | F89: PPS2638005030114 | G89: 在售 | H89: 北美进口FAS级樱桃木：温润木色流畅纹路。整柜原木纹理细腻，自然和煦。 12mm超厚钢化玻璃台面：安全无虞。防冲击耐高温，晶莹透亮让光线自由呼吸。 长虹玻璃侧板：光影交织美学设计。空气感线条，光与影的浪漫在时刻中隽永驻留。 双层式置物设计：开放取物不拘束。躺着也好拿，日用小物伸手可得。 条块镂空底板：光线潺潺倾泻而下。分层收纳条理分明，插线板可隐藏轻松理线。 迷人夜灯：亮度无极可调。一键点亮光影艺术，潺潺微光静谧美梦相伴。 一体式钢化台面：清爽利落方便置物。台面玻璃倒圆，无惧磕碰亲肤好用。 侧边预留走线间隙：桌面更清爽。充电更便捷，告别杂乱线材。 背后预留踢脚线位：方便贴墙。高度刚刚好，随手放置很方便。 | I89: 德国进口AA级榉木 | J89: 侧板：玻璃 | K89: 长度：430mm 深度：510mm 高度：460mm | L89: 长度可任意定制；深度可任意定制；高度可任意定制； | M89: . | N89: ✅ 可导入 | O89: ✓
A90: PPS26380050301 | B90: 卧室-床头柜 | C90: 畔色樱桃木轻盈边柜 |樱桃木玻璃床头柜 |黑色玻璃床头柜 |樱桃木玻璃边柜 | D90: https://img.alicdn.com/imgextra/i4/2215699812811/O1CN01aV7b7w1WdUTd0Dctr_!!2215699812811.jpg | E90: 轻盈边柜-樱桃木-玻璃底座 | F90: PPS2638005030115 | G90: 在售 | H90: 北美进口FAS级樱桃木：温润木色流畅纹路。整柜原木纹理细腻，自然和煦。 12mm超厚钢化玻璃台面：安全无虞。防冲击耐高温，晶莹透亮让光线自由呼吸。 长虹玻璃侧板：光影交织美学设计。空气感线条，光与影的浪漫在时刻中隽永驻留。 双层式置物设计：开放取物不拘束。躺着也好拿，日用小物伸手可得。 条块镂空底板：光线潺潺倾泻而下。分层收纳条理分明，插线板可隐藏轻松理线。 迷人夜灯：亮度无极可调。一键点亮光影艺术，潺潺微光静谧美梦相伴。 一体式钢化台面：清爽利落方便置物。台面玻璃倒圆，无惧磕碰亲肤好用。 侧边预留走线间隙：桌面更清爽。充电更便捷，告别杂乱线材。 背后预留踢脚线位：方便贴墙。高度刚刚好，随手放置很方便。 | I90: 北美进口FAS级樱桃木 | J90: 侧板：玻璃 | K90: 长度：430mm 深度：510mm 高度：460mm | L90: 长度可任意定制；深度可任意定制；高度可任意定制； | M90: . | N90: ✅ 可导入 | O90: ✓
A91: PPS26380050301 | B91: 卧室-床头柜 | C91: 畔色樱桃木轻盈边柜 |樱桃木玻璃床头柜 |黑色玻璃床头柜 |樱桃木玻璃边柜 | D91: https://img.alicdn.com/imgextra/i4/2215699812811/O1CN01aV7b7w1WdUTd0Dctr_!!2215699812811.jpg | E91: 轻盈边柜-黑胡桃木-玻璃底座 | F91: PPS2638005030116 | G91: 在售 | H91: 北美进口FAS级樱桃木：温润木色流畅纹路。整柜原木纹理细腻，自然和煦。 12mm超厚钢化玻璃台面：安全无虞。防冲击耐高温，晶莹透亮让光线自由呼吸。 长虹玻璃侧板：光影交织美学设计。空气感线条，光与影的浪漫在时刻中隽永驻留。 双层式置物设计：开放取物不拘束。躺着也好拿，日用小物伸手可得。 条块镂空底板：光线潺潺倾泻而下。分层收纳条理分明，插线板可隐藏轻松理线。 迷人夜灯：亮度无极可调。一键点亮光影艺术，潺潺微光静谧美梦相伴。 一体式钢化台面：清爽利落方便置物。台面玻璃倒圆，无惧磕碰亲肤好用。 侧边预留走线间隙：桌面更清爽。充电更便捷，告别杂乱线材。 背后预留踢脚线位：方便贴墙。高度刚刚好，随手放置很方便。 | I91: 北美进口FAS级黑胡桃木 | J91: 侧板：玻璃 | K91: 长度：430mm 深度：510mm 高度：460mm | L91: 长度可任意定制；深度可任意定制；高度可任意定制； | M91: . | N91: ✅ 可导入 | O91: ✓
A92: PPS26390070315 | B92: 卧室-床头柜 | C92: 畔色樱桃木床头窄柜 | 樱桃木窄床头柜 | D92: https://img.alicdn.com/imgextra/i3/2215699812811/O1CN01Iuil5d1WdUTXCr2Tl_!!2215699812811.jpg | E92: 樱桃木床头窄柜-标准宽度 | F92: PPS2639007031511 | G92: 在售 | H92: 北美进口FAS级樱桃木：温润木色流畅纹路。整柜原木天然纹理，温润细腻。 超窄设计：留出床边大空间。窄身床头柜小空间专属，台面大深度置物无忧。 双抽分区收纳：上层日常小物轻松取放。下抽囤货随心储放，收纳井井有条。 一体式实木台面：清爽利落方便置物。摒弃繁杂线条，台面浑然一体。 定制拉手：丝滑省力。轻巧设计，舒适握感。 随取随用：合适高度的台面。美的恰好，温雅床头气质。 背板内收设计：轻松理线。后部走线孔，背板内收避让插座。 排插放置位预留：线材有序台面清爽。预留走线槽，告别杂乱。 底部高空间：扫地机清扫无忧。清洁无死角，方便打理。 全柜圆润倒角：舒适亲肤磕碰无忧。边缘温润，安心使用。 预留踢脚线位：方便贴墙。畔色柜30cm，衣柜开门顺畅抽屉可用。 | I92: 北美进口FAS级樱桃木 | J92: 把手：不锈钢 | K92: 长度：340mm 深度：400mm 高度：480mm | L92: 长度可任意定制；深度可任意定制；高度可任意定制； | M92: . | N92: ✅ 可导入 | O92: ✓
...

Sheet 2-定价总表
A1: 2-定价总表 | CC1: 本表共 490 行数据，132 行存在问题。 主要问题: 数值含文本×111、公式错误×16、关键字段为空×5 导入将丢失的列(无系统字段映射): 图片链接、大促利润、即时毛利率、平台费率、税费、物流费用、安装费用、总出厂成本、木作成本、打包、外采配件成本、岩板、抽屉轨道、灯带、玻璃、电力轨道、打包纸片、铁销、连接片、铝合金轨道、塑料轨道、mini把手、免钉胶、雕刻、亚克力条、...
A2: 产品编码 | B2: 产品名称 | C2: SKU | D2: SKU编码 | E2: 图片链接 | F2: 产品大小类型 | G2: 标价计算 | H2: 日常价/单品宝 | I2: 小促价（超级立减） | J2: 中促价（88券活动） | K2: 大促到手价（双11） | L2: 大促利润 | M2: 即时毛利率 | N2: 会计总成本 | O2: 平台费率 | P2: 税费 | Q2: 物理总成本 | R2: 物流费用 | S2: 安装费用 | T2: 总出厂成本 | U2: 木作成本 | V2: 打包 | W2: 外采配件成本 | X2: 岩板 | Y2: 抽屉轨道 | Z2: 灯带 | AA2: 玻璃 | AB2: 电力轨道 | AC2: 打包纸片 | AD2: 铁销 | AE2: 连接片 | AF2: 铝合金轨道 | AG2: 塑料轨道 | AH2: mini把手 | AI2: 免钉胶 | AJ2: 雕刻 | AK2: 亚克力条 | AL2: 预埋套杆 | AM2: 理线架+插排 | AN2: 背板 | AO2: 装饰条（不锈钢） | AP2: 腿部 | AQ2: 软包 | AR2: 床铺板 | AS2: 其他 | AT2: 外配件说明 | AU2: 配件备注 | AV2: 小红书商品ID | AW2: 小红书SKU名 | AX2: 小红书SKU ID | AY2: RN 标价 | AZ2: RN单品宝报名价 | BA2: RN大促优惠比例 | BB2: RN大促价格 | BC2: 淘宝商品ID | BD2: 淘宝链接 | BE2: 淘宝SKU ID | BF2: 淘宝活动报名价 | BG2: 店内活动-店铺宝 | BH2: 店内活动-到手价 | BI2: 无国补中促-平台立减 12% | BJ2: 无国补中促-店铺宝 | BK2: 无国补中促-买家到手价（不含消费券） | BL2: 无国补中促-88VIP佣金 | BM2: 无国补中促-店铺实收价格 | BN2: 无国补中促-88vip买家最终到手价 | BO2: 无国补大促-平台立减 12% | BP2: 无国补大促-店铺宝设置 | BQ2: 无国补大促-买家到手价（不含消费券） | BR2: 无国补大促-88VIP佣金 | BS2: 无国补大促-店铺实收价格 | BT2: 无国补大促-买家最终到手价 | BU2: 备注 | CB2: 导入校验 | CC2: ⚠️问题标注
A3: PPS26330070320 | B3: 畔色榉木无边床 |榉木金属腿床 | C3: 榉木无边床-1.2米-榉木铺板 | D3: PPS2633007032011 | E3: https://img.alicdn.com/imgextra/i1/2215699812811/O1CN01weGhhJ1WdUTWXDll4_!!2215699812811.jpg | F3: 中型 | G3: =Q3/0.4 | H3: =G3*0.75 | I3: =Q3 / (0.855 - 0.02 - 0.006) | J3: =Q3 / (0.87 - 0.02 - 0.006) | K3: =Q3 / (0.9 - 0.02 - 0.006) | L3: =K3-N3 | M3: =L3/K3 | N3: =O3+P3+Q3 | O3: =K3*0.006 | P3: =K3*0.02 | Q3: =SUM(R3:T3) | R3: =IF(F3="大型",700,IF(F3="中型",300,IF(F3="小型",80,0))) | S3: =IF(F3="大型",150,IF(F3="中型",100,IF(F3="小型",0,0))) | T3: =SUM(U3:W3) | U3: 1360 | V3: 140 | W3: =SUM(X3:AS3) | X3: 0 | Y3: 0 | Z3: 0 | AA3: 0 | AB3: 0 | AC3: 0 | AD3: 0 | AE3: 0 | AF3: 0 | AG3: 0 | AH3: 0 | AI3: 0 | AJ3: 0 | AK3: 0 | AL3: 0 | AM3: 0 | AN3: 0 | AO3: 0 | AP3: 240 | AQ3: 0 | AR3: 590 | AS3: 0 | AV3: 69f6f21130d08600013a69ea | AW3: 榉木无边床-1.2米-榉木铺板 | AX3: 69f6f21130d08600013a69eb | AY3: =H3 | AZ3: =BB3/(1-BA3) | BA3: 0.15 | BB3: =K3*0.96 | BC3: 1038062316046 | BD3: 待定 | BF3: =H3 | BG3: =BH3/BF3 | BH3: =I3 | BI3: =1-12% | BJ3: =BK3/(BF3-BF3*(1-BI3)) | BK3: =BM3/(1-BL3) | BL3: 0.01 | BM3: =J3 | BN3: =IF(BK3>=1500,BK3-150,IF(BK3>=800,BK3-80,IF(BK3>=500,BK3-50,IF(BK3>=200,BK3-20,BK3)))) | BO3: =1-12% | BP3: =BQ3/(BF3-BF3*(1-BO3)) | BQ3: =BS3/(1-BR3) | BR3: 0 | BS3: =K3 | BT3: =IF(BQ3>=1500,BQ3-150,IF(BQ3>=800,BQ3-80,IF(BQ3>=500,BQ3-50,IF(BQ3>=200,BQ3-20,BQ3)))) | CB3: ✅ 可导入 | CC3: ✓
A4: PPS26330070320 | B4: 畔色榉木无边床 |榉木金属腿床 | C4: 榉木无边床-1.35米-榉木铺板 | D4: PPS2633007032012 | E4: https://img.alicdn.com/imgextra/i1/2215699812811/O1CN01weGhhJ1WdUTWXDll4_!!2215699812811.jpg | F4: 中型 | G4: =Q4/0.4 | H4: =G4*0.75 | I4: =Q4 / (0.855 - 0.02 - 0.006) | J4: =Q4 / (0.87 - 0.02 - 0.006) | K4: =Q4 / (0.9 - 0.02 - 0.006) | L4: =K4-N4 | M4: =L4/K4 | N4: =O4+P4+Q4 | O4: =K4*0.006 | P4: =K4*0.02 | Q4: =SUM(R4:T4) | R4: =IF(F4="大型",700,IF(F4="中型",300,IF(F4="小型",80,0))) | S4: =IF(F4="大型",150,IF(F4="中型",100,IF(F4="小型",0,0))) | T4: =SUM(U4:W4) | U4: 1390 | V4: 140 | W4: =SUM(X4:AS4) | X4: 0 | Y4: 0 | Z4: 0 | AA4: 0 | AB4: 0 | AC4: 0 | AD4: 0 | AE4: 0 | AF4: 0 | AG4: 0 | AH4: 0 | AI4: 0 | AJ4: 0 | AK4: 0 | AL4: 0 | AM4: 0 | AN4: 0 | AO4: 0 | AP4: 240 | AQ4: 0 | AR4: 610 | AS4: 0 | AV4: 69f6f21130d08600013a69ea | AW4: 榉木无边床-1.35米-榉木铺板 | AX4: 69f6f21130d08600013a69ee | AY4: =H4 | AZ4: =BB4/(1-BA4) | BA4: 0.15 | BB4: =K4*0.96 | BC4: 1038062316046 | BD4: 待定 | BF4: =H4 | BG4: =BH4/BF4 | BH4: =I4 | BI4: =1-12% | BJ4: =BK4/(BF4-BF4*(1-BI4)) | BK4: =BM4/(1-BL4) | BL4: 0.01 | BM4: =J4 | BN4: =IF(BK4>=1500,BK4-150,IF(BK4>=800,BK4-80,IF(BK4>=500,BK4-50,IF(BK4>=200,BK4-20,BK4)))) | BO4: =1-12% | BP4: =BQ4/(BF4-BF4*(1-BO4)) | BQ4: =BS4/(1-BR4) | BR4: 0 | BS4: =K4 | BT4: =IF(BQ4>=1500,BQ4-150,IF(BQ4>=800,BQ4-80,IF(BQ4>=500,BQ4-50,IF(BQ4>=200,BQ4-20,BQ4)))) | CB4: ✅ 可导入 | CC4: ✓
A5: PPS26330070320 | B5: 畔色榉木无边床 |榉木金属腿床 | C5: 榉木无边床-1.5米-榉木铺板 | D5: PPS2633007032013 | E5: https://img.alicdn.com/imgextra/i1/2215699812811/O1CN01weGhhJ1WdUTWXDll4_!!2215699812811.jpg | F5: 中型 | G5: =Q5/0.4 | H5: =G5*0.75 | I5: =Q5 / (0.855 - 0.02 - 0.006) | J5: =Q5 / (0.87 - 0.02 - 0.006) | K5: =Q5 / (0.9 - 0.02 - 0.006) | L5: =K5-N5 | M5: =L5/K5 | N5: =O5+P5+Q5 | O5: =K5*0.006 | P5: =K5*0.02 | Q5: =SUM(R5:T5) | R5: =IF(F5="大型",700,IF(F5="中型",300,IF(F5="小型",80,0))) | S5: =IF(F5="大型",150,IF(F5="中型",100,IF(F5="小型",0,0))) | T5: =SUM(U5:W5) | U5: 1420 | V5: 150 | W5: =SUM(X5:AS5) | X5: 0 | Y5: 0 | Z5: 0 | AA5: 0 | AB5: 0 | AC5: 0 | AD5: 0 | AE5: 0 | AF5: 0 | AG5: 0 | AH5: 0 | AI5: 0 | AJ5: 0 | AK5: 0 | AL5: 0 | AM5: 0 | AN5: 0 | AO5: 0 | AP5: 240 | AQ5: 0 | AR5: 630 | AS5: 0 | AV5: 69f6f21130d08600013a69ea | AW5: 榉木无边床-1.5米-榉木铺板 | AX5: 69f6f21130d08600013a69f1 | AY5: =H5 | AZ5: =BB5/(1-BA5) | BA5: 0.15 | BB5: =K5*0.96 | BC5: 1038062316046 | BD5: 待定 | BF5: =H5 | BG5: =BH5/BF5 | BH5: =I5 | BI5: =1-12% | BJ5: =BK5/(BF5-BF5*(1-BI5)) | BK5: =BM5/(1-BL5) | BL5: 0.01 | BM5: =J5 | BN5: =IF(BK5>=1500,BK5-150,IF(BK5>=800,BK5-80,IF(BK5>=500,BK5-50,IF(BK5>=200,BK5-20,BK5)))) | BO5: =1-12% | BP5: =BQ5/(BF5-BF5*(1-BO5)) | BQ5: =BS5/(1-BR5) | BR5: 0 | BS5: =K5 | BT5: =IF(BQ5>=1500,BQ5-150,IF(BQ5>=800,BQ5-80,IF(BQ5>=500,BQ5-50,IF(BQ5>=200,BQ5-20,BQ5)))) | CB5: ✅ 可导入 | CC5: ✓
A6: PPS26330070320 | B6: 畔色榉木无边床 |榉木金属腿床 | C6: 榉木无边床-1.8米-榉木铺板 | D6: PPS2633007032014 | E6: https://img.alicdn.com/imgextra/i1/2215699812811/O1CN01weGhhJ1WdUTWXDll4_!!2215699812811.jpg | F6: 中型 | G6: =Q6/0.4 | H6: =G6*0.75 | I6: =Q6 / (0.855 - 0.02 - 0.006) | J6: =Q6 / (0.87 - 0.02 - 0.006) | K6: =Q6 / (0.9 - 0.02 - 0.006) | L6: =K6-N6 | M6: =L6/K6 | N6: =O6+P6+Q6 | O6: =K6*0.006 | P6: =K6*0.02 | Q6: =SUM(R6:T6) | R6: =IF(F6="大型",700,IF(F6="中型",300,IF(F6="小型",80,0))) | S6: =IF(F6="大型",150,IF(F6="中型",100,IF(F6="小型",0,0))) | T6: =SUM(U6:W6) | U6: 1500 | V6: 150 | W6: =SUM(X6:AS6) | X6: 0 | Y6: 0 | Z6: 0 | AA6: 0 | AB6: 0 | AC6: 0 | AD6: 0 | AE6: 0 | AF6: 0 | AG6: 0 | AH6: 0 | AI6: 0 | AJ6: 0 | AK6: 0 | AL6: 0 | AM6: 0 | AN6: 0 | AO6: 0 | AP6: 240 | AQ6: 0 | AR6: 650 | AS6: 0 | AV6: 69f6f21130d08600013a69ea | AW6: 榉木无边床-1.8米-榉木铺板 | AX6: 69f6f21130d08600013a69f4 | AY6: =H6 | AZ6: =BB6/(1-BA6) | BA6: 0.15 | BB6: =K6*0.96 | BC6: 1038062316046 | BD6: 待定 | BF6: =H6 | BG6: =BH6/BF6 | BH6: =I6 | BI6: =1-12% | BJ6: =BK6/(BF6-BF6*(1-BI6)) | BK6: =BM6/(1-BL6) | BL6: 0.01 | BM6: =J6 | BN6: =IF(BK6>=1500,BK6-150,IF(BK6>=800,BK6-80,IF(BK6>=500,BK6-50,IF(BK6>=200,BK6-20,BK6)))) | BO6: =1-12% | BP6: =BQ6/(BF6-BF6*(1-BO6)) | BQ6: =BS6/(1-BR6) | BR6: 0 | BS6: =K6 | BT6: =IF(BQ6>=1500,BQ6-150,IF(BQ6>=800,BQ6-80,IF(BQ6>=500,BQ6-50,IF(BQ6>=200,BQ6-20,BQ6)))) | CB6: ✅ 可导入 | CC6: ✓
A7: PPS26330070320 | B7: 畔色榉木无边床 |榉木金属腿床 | C7: 榉木无边床-1.2米-松木铺板 | D7: PPS2633007032015 | E7: https://img.alicdn.com/imgextra/i1/2215699812811/O1CN01weGhhJ1WdUTWXDll4_!!2215699812811.jpg | F7: 中型 | G7: =Q7/0.4 | H7: =G7*0.75 | I7: =Q7 / (0.855 - 0.02 - 0.006) | J7: =Q7 / (0.87 - 0.02 - 0.006) | K7: =Q7 / (0.9 - 0.02 - 0.006) | L7: =K7-N7 | M7: =L7/K7 | N7: =O7+P7+Q7 | O7: =K7*0.006 | P7: =K7*0.02 | Q7: =SUM(R7:T7) | R7: =IF(F7="大型",700,IF(F7="中型",300,IF(F7="小型",80,0))) | S7: =IF(F7="大型",150,IF(F7="中型",100,IF(F7="小型",0,0))) | T7: =SUM(U7:W7) | U7: 1390 | V7: 140 | W7: =SUM(X7:AS7) | X7: 0 | Y7: 0 | Z7: 0 | AA7: 0 | AB7: 0 | AC7: 0 | AD7: 0 | AE7: 0 | AF7: 0 | AG7: 0 | AH7: 0 | AI7: 0 | AJ7: 0 | AK7: 0 | AL7: 0 | AM7: 0 | AN7: 0 | AO7: 0 | AP7: 240 | AQ7: 0 | AR7: 160 | AS7: 0 | AV7: 69f6f21130d08600013a69ea | AW7: 榉木无边床-1.2米-松木铺板 | AX7: 69f6f21130d08600013a69f7 | AY7: =H7 | AZ7: =BB7/(1-BA7) | BA7: 0.15 | BB7: =K7*0.96 | BC7: 1038062316046 | BD7: 待定 | BF7: =H7 | BG7: =BH7/BF7 | BH7: =I7 | BI7: =1-12% | BJ7: =BK7/(BF7-BF7*(1-BI7)) | BK7: =BM7/(1-BL7) | BL7: 0.01 | BM7: =J7 | BN7: =IF(BK7>=1500,BK7-150,IF(BK7>=800,BK7-80,IF(BK7>=500,BK7-50,IF(BK7>=200,BK7-20,BK7)))) | BO7: =1-12% | BP7: =BQ7/(BF7-BF7*(1-BO7)) | BQ7: =BS7/(1-BR7) | BR7: 0 | BS7: =K7 | BT7: =IF(BQ7>=1500,BQ7-150,IF(BQ7>=800,BQ7-80,IF(BQ7>=500,BQ7-50,IF(BQ7>=200,BQ7-20,BQ7)))) | CB7: ✅ 可导入 | CC7: ✓
A8: PPS26330070320 | B8: 畔色榉木无边床 |榉木金属腿床 | C8: 榉木无边床-1.35米-松木铺板 | D8: PPS2633007032016 | E8: https://img.alicdn.com/imgextra/i1/2215699812811/O1CN01weGhhJ1WdUTWXDll4_!!2215699812811.jpg | F8: 中型 | G8: =Q8/0.4 | H8: =G8*0.75 | I8: =Q8 / (0.855 - 0.02 - 0.006) | J8: =Q8 / (0.87 - 0.02 - 0.006) | K8: =Q8 / (0.9 - 0.02 - 0.006) | L8: =K8-N8 | M8: =L8/K8 | N8: =O8+P8+Q8 | O8: =K8*0.006 | P8: =K8*0.02 | Q8: =SUM(R8:T8) | R8: =IF(F8="大型",700,IF(F8="中型",300,IF(F8="小型",80,0))) | S8: =IF(F8="大型",150,IF(F8="中型",100,IF(F8="小型",0,0))) | T8: =SUM(U8:W8) | U8: 1420 | V8: 140 | W8: =SUM(X8:AS8) | X8: 0 | Y8: 0 | Z8: 0 | AA8: 0 | AB8: 0 | AC8: 0 | AD8: 0 | AE8: 0 | AF8: 0 | AG8: 0 | AH8: 0 | AI8: 0 | AJ8: 0 | AK8: 0 | AL8: 0 | AM8: 0 | AN8: 0 | AO8: 0 | AP8: 240 | AQ8: 0 | AR8: 180 | AS8: 0 | AV8: 69f6f21130d08600013a69ea | AW8: 榉木无边床-1.35米-松木铺板 | AX8: 69f6f21130d08600013a69fa | AY8: =H8 | AZ8: =BB8/(1-BA8) | BA8: 0.15 | BB8: =K8*0.96 | BC8: 1038062316046 | BD8: 待定 | BF8: =H8 | BG8: =BH8/BF8 | BH8: =I8 | BI8: =1-12% | BJ8: =BK8/(BF8-BF8*(1-BI8)) | BK8: =BM8/(1-BL8) | BL8: 0.01 | BM8: =J8 | BN8: =IF(BK8>=1500,BK8-150,IF(BK8>=800,BK8-80,IF(BK8>=500,BK8-50,IF(BK8>=200,BK8-20,BK8)))) | BO8: =1-12% | BP8: =BQ8/(BF8-BF8*(1-BO8)) | BQ8: =BS8/(1-BR8) | BR8: 0 | BS8: =K8 | BT8: =IF(BQ8>=1500,BQ8-150,IF(BQ8>=800,BQ8-80,IF(BQ8>=500,BQ8-50,IF(BQ8>=200,BQ8-20,BQ8)))) | CB8: ✅ 可导入 | CC8: ✓
A9: PPS26330070320 | B9: 畔色榉木无边床 |榉木金属腿床 | C9: 榉木无边床-1.5米-松木铺板 | D9: PPS2633007032017 | E9: https://img.alicdn.com/imgextra/i1/2215699812811/O1CN01weGhhJ1WdUTWXDll4_!!2215699812811.jpg | F9: 中型 | G9: =Q9/0.4 | H9: =G9*0.75 | I9: =Q9 / (0.855 - 0.02 - 0.006) | J9: =Q9 / (0.87 - 0.02 - 0.006) | K9: =Q9 / (0.9 - 0.02 - 0.006) | L9: =K9-N9 | M9: =L9/K9 | N9: =O9+P9+Q9 | O9: =K9*0.006 | P9: =K9*0.02 | Q9: =SUM(R9:T9) | R9: =IF(F9="大型",700,IF(F9="中型",300,IF(F9="小型",80,0))) | S9: =IF(F9="大型",150,IF(F9="中型",100,IF(F9="小型",0,0))) | T9: =SUM(U9:W9) | U9: 1470 | V9: 150 | W9: =SUM(X9:AS9) | X9: 0 | Y9: 0 | Z9: 0 | AA9: 0 | AB9: 0 | AC9: 0 | AD9: 0 | AE9: 0 | AF9: 0 | AG9: 0 | AH9: 0 | AI9: 0 | AJ9: 0 | AK9: 0 | AL9: 0 | AM9: 0 | AN9: 0 | AO9: 0 | AP9: 240 | AQ9: 0 | AR9: 180 | AS9: 0 | AV9: 69f6f21130d08600013a69ea | AW9: 榉木无边床-1.5米-松木铺板 | AX9: 69f6f21130d08600013a69fd | AY9: =H9 | AZ9: =BB9/(1-BA9) | BA9: 0.15 | BB9: =K9*0.96 | BC9: 1038062316046 | BD9: 待定 | BF9: =H9 | BG9: =BH9/BF9 | BH9: =I9 | BI9: =1-12% | BJ9: =BK9/(BF9-BF9*(1-BI9)) | BK9: =BM9/(1-BL9) | BL9: 0.01 | BM9: =J9 | BN9: =IF(BK9>=1500,BK9-150,IF(BK9>=800,BK9-80,IF(BK9>=500,BK9-50,IF(BK9>=200,BK9-20,BK9)))) | BO9: =1-12% | BP9: =BQ9/(BF9-BF9*(1-BO9)) | BQ9: =BS9/(1-BR9) | BR9: 0 | BS9: =K9 | BT9: =IF(BQ9>=1500,BQ9-150,IF(BQ9>=800,BQ9-80,IF(BQ9>=500,BQ9-50,IF(BQ9>=200,BQ9-20,BQ9)))) | CB9: ✅ 可导入 | CC9: ✓
A10: PPS26330070320 | B10: 畔色榉木无边床 |榉木金属腿床 | C10: 榉木无边床-1.8米-松木铺板 | D10: PPS2633007032018 | E10: https://img.alicdn.com/imgextra/i1/2215699812811/O1CN01weGhhJ1WdUTWXDll4_!!2215699812811.jpg | F10: 中型 | G10: =Q10/0.4 | H10: =G10*0.75 | I10: =Q10 / (0.855 - 0.02 - 0.006) | J10: =Q10 / (0.87 - 0.02 - 0.006) | K10: =Q10 / (0.9 - 0.02 - 0.006) | L10: =K10-N10 | M10: =L10/K10 | N10: =O10+P10+Q10 | O10: =K10*0.006 | P10: =K10*0.02 | Q10: =SUM(R10:T10) | R10: =IF(F10="大型",700,IF(F10="中型",300,IF(F10="小型",80,0))) | S10: =IF(F10="大型",150,IF(F10="中型",100,IF(F10="小型",0,0))) | T10: =SUM(U10:W10) | U10: 1500 | V10: 150 | W10: =SUM(X10:AS10) | X10: 0 | Y10: 0 | Z10: 0 | AA10: 0 | AB10: 0 | AC10: 0 | AD10: 0 | AE10: 0 | AF10: 0 | AG10: 0 | AH10: 0 | AI10: 0 | AJ10: 0 | AK10: 0 | AL10: 0 | AM10: 0 | AN10: 0 | AO10: 0 | AP10: 240 | AQ10: 0 | AR10: 200 | AS10: 0 | AV10: 69f6f21130d08600013a69ea | AW10: 榉木无边床-1.8米-松木铺板 | AX10: 69f6f21130d08600013a6a00 | AY10: =H10 | AZ10: =BB10/(1-BA10) | BA10: 0.15 | BB10: =K10*0.96 | BC10: 1038062316046 | BD10: 待定 | BF10: =H10 | BG10: =BH10/BF10 | BH10: =I10 | BI10: =1-12% | BJ10: =BK10/(BF10-BF10*(1-BI10)) | BK10: =BM10/(1-BL10) | BL10: 0.01 | BM10: =J10 | BN10: =IF(BK10>=1500,BK10-150,IF(BK10>=800,BK10-80,IF(BK10>=500,BK10-50,IF(BK10>=200,BK10-20,BK10)))) | BO10: =1-12% | BP10: =BQ10/(BF10-BF10*(1-BO10)) | BQ10: =BS10/(1-BR10) | BR10: 0 | BS10: =K10 | BT10: =IF(BQ10>=1500,BQ10-150,IF(BQ10>=800,BQ10-80,IF(BQ10>=500,BQ10-50,IF(BQ10>=200,BQ10-20,BQ10)))) | CB10: ✅ 可导入 | CC10: ✓
A11: PPS26330080322 | B11: 畔色榉木柔光双人床 |榉木小灯床 | C11: 榉木柔光床-1.2米-榉木铺板 | D11: PPS2633008032211 | E11: https://img.alicdn.com/imgextra/i3/2215699812811/O1CN011b8ljX1WdUTWEOKNH_!!2215699812811.jpg | F11: 中型 | G11: =Q11/0.4 | H11: =G11*0.75 | I11: =Q11 / (0.855 - 0.02 - 0.006) | J11: =Q11 / (0.87 - 0.02 - 0.006) | K11: =Q11 / (0.9 - 0.02 - 0.006) | L11: =K11-N11 | M11: =L11/K11 | N11: =O11+P11+Q11 | O11: =K11*0.006 | P11: =K11*0.02 | Q11: =SUM(R11:T11) | R11: =IF(F11="大型",700,IF(F11="中型",300,IF(F11="小型",80,0))) | S11: =IF(F11="大型",150,IF(F11="中型",100,IF(F11="小型",0,0))) | T11: =SUM(U11:W11) | U11: 2010 | V11: 140 | W11: =SUM(X11:AS11) | X11: 0 | Y11: 0 | Z11: 100 | AA11: 0 | AB11: 0 | AC11: 0 | AD11: 0 | AE11: 0 | AF11: 0 | AG11: 0 | AH11: 0 | AI11: 0 | AJ11: 0 | AK11: 0 | AL11: 0 | AM11: 0 | AN11: 0 | AO11: 0 | AP11: 0 | AQ11: 0 | AR11: 590 | AS11: 0 | AU11: 外面价格：1.8床铺板打孔+纸箱+整片=23*22+50=556 1.5规格是536，1.2规格是516 | AV11: 69f6f3de6eeaf7000137dca2 | AW11: 榉木柔光床-1.2米-榉木铺板 | AX11: 69f6f3de6eeaf7000137dca3 | AY11: =H11 | AZ11: =BB11/(1-BA11) | BA11: 0.15 | BB11: =K11*0.96 | BC11: 1036279566778 | BD11: 待定 | BF11: =H11 | BG11: =BH11/BF11 | BH11: =I11 | BI11: =1-12% | BJ11: =BK11/(BF11-BF11*(1-BI11)) | BK11: =BM11/(1-BL11) | BL11: 0.01 | BM11: =J11 | BN11: =IF(BK11>=1500,BK11-150,IF(BK11>=800,BK11-80,IF(BK11>=500,BK11-50,IF(BK11>=200,BK11-20,BK11)))) | BO11: =1-12% | BP11: =BQ11/(BF11-BF11*(1-BO11)) | BQ11: =BS11/(1-BR11) | BR11: 0 | BS11: =K11 | BT11: =IF(BQ11>=1500,BQ11-150,IF(BQ11>=800,BQ11-80,IF(BQ11>=500,BQ11-50,IF(BQ11>=200,BQ11-20,BQ11)))) | CB11: ✅ 可导入 | CC11: ✓
A12: PPS26330080322 | B12: 畔色榉木柔光双人床 |榉木小灯床 | C12: 榉木柔光床-1.35米-榉木铺板 | D12: PPS2633008032212 | E12: https://img.alicdn.com/imgextra/i3/2215699812811/O1CN011b8ljX1WdUTWEOKNH_!!2215699812811.jpg | F12: 中型 | G12: =Q12/0.4 | H12: =G12*0.75 | I12: =Q12 / (0.855 - 0.02 - 0.006) | J12: =Q12 / (0.87 - 0.02 - 0.006) | K12: =Q12 / (0.9 - 0.02 - 0.006) | L12: =K12-N12 | M12: =L12/K12 | N12: =O12+P12+Q12 | O12: =K12*0.006 | P12: =K12*0.02 | Q12: =SUM(R12:T12) | R12: =IF(F12="大型",700,IF(F12="中型",300,IF(F12="小型",80,0))) | S12: =IF(F12="大型",150,IF(F12="中型",100,IF(F12="小型",0,0))) | T12: =SUM(U12:W12) | U12: 2040 | V12: 140 | W12: =SUM(X12:AS12) | X12: 0 | Y12: 0 | Z12: 100 | AA12: 0 | AB12: 0 | AC12: 0 | AD12: 0 | AE12: 0 | AF12: 0 | AG12: 0 | AH12: 0 | AI12: 0 | AJ12: 0 | AK12: 0 | AL12: 0 | AM12: 0 | AN12: 0 | AO12: 0 | AP12: 0 | AQ12: 0 | AR12: 610 | AS12: 0 | AU12: 外面价格：1.8床铺板打孔+纸箱+整片=23*22+50=556 1.5规格是536，1.2规格是516 | AV12: 69f6f3de6eeaf7000137dca2 | AW12: 榉木柔光床-1.35米-榉木铺板 | AX12: 69f6f3de6eeaf7000137dca6 | AY12: =H12 | AZ12: =BB12/(1-BA12) | BA12: 0.15 | BB12: =K12*0.96 | BC12: 1036279566778 | BD12: 待定 | BF12: =H12 | BG12: =BH12/BF12 | BH12: =I12 | BI12: =1-12% | BJ12: =BK12/(BF12-BF12*(1-BI12)) | BK12: =BM12/(1-BL12) | BL12: 0.01 | BM12: =J12 | BN12: =IF(BK12>=1500,BK12-150,IF(BK12>=800,BK12-80,IF(BK12>=500,BK12-50,IF(BK12>=200,BK12-20,BK12)))) | BO12: =1-12% | BP12: =BQ12/(BF12-BF12*(1-BO12)) | BQ12: =BS12/(1-BR12) | BR12: 0 | BS12: =K12 | BT12: =IF(BQ12>=1500,BQ12-150,IF(BQ12>=800,BQ12-80,IF(BQ12>=500,BQ12-50,IF(BQ12>=200,BQ12-20,BQ12)))) | CB12: ✅ 可导入 | CC12: ✓
A13: PPS26330080322 | B13: 畔色榉木柔光双人床 |榉木小灯床 | C13: 榉木柔光床-1.5米-榉木铺板 | D13: PPS2633008032213 | E13: https://img.alicdn.com/imgextra/i3/2215699812811/O1CN011b8ljX1WdUTWEOKNH_!!2215699812811.jpg | F13: 中型 | G13: =Q13/0.4 | H13: =G13*0.75 | I13: =Q13 / (0.855 - 0.02 - 0.006) | J13: =Q13 / (0.87 - 0.02 - 0.006) | K13: =Q13 / (0.9 - 0.02 - 0.006) | L13: =K13-N13 | M13: =L13/K13 | N13: =O13+P13+Q13 | O13: =K13*0.006 | P13: =K13*0.02 | Q13: =SUM(R13:T13) | R13: =IF(F13="大型",700,IF(F13="中型",300,IF(F13="小型",80,0))) | S13: =IF(F13="大型",150,IF(F13="中型",100,IF(F13="小型",0,0))) | T13: =SUM(U13:W13) | U13: 2120 | V13: 150 | W13: =SUM(X13:AS13) | X13: 0 | Y13: 0 | Z13: 100 | AA13: 0 | AB13: 0 | AC13: 0 | AD13: 0 | AE13: 0 | AF13: 0 | AG13: 0 | AH13: 0 | AI13: 0 | AJ13: 0 | AK13: 0 | AL13: 0 | AM13: 0 | AN13: 0 | AO13: 0 | AP13: 0 | AQ13: 0 | AR13: 630 | AS13: 0 | AU13: 外面价格：1.8床铺板打孔+纸箱+整片=23*22+50=556 1.5规格是536，1.2规格是516 | AV13: 69f6f3de6eeaf7000137dca2 | AW13: 榉木柔光床-1.5米-榉木铺板 | AX13: 69f6f3de6eeaf7000137dca9 | AY13: =H13 | AZ13: =BB13/(1-BA13) | BA13: 0.15 | BB13: =K13*0.96 | BC13: 1036279566778 | BD13: 待定 | BF13: =H13 | BG13: =BH13/BF13 | BH13: =I13 | BI13: =1-12% | BJ13: =BK13/(BF13-BF13*(1-BI13)) | BK13: =BM13/(1-BL13) | BL13: 0.01 | BM13: =J13 | BN13: =IF(BK13>=1500,BK13-150,IF(BK13>=800,BK13-80,IF(BK13>=500,BK13-50,IF(BK13>=200,BK13-20,BK13)))) | BO13: =1-12% | BP13: =BQ13/(BF13-BF13*(1-BO13)) | BQ13: =BS13/(1-BR13) | BR13: 0 | BS13: =K13 | BT13: =IF(BQ13>=1500,BQ13-150,IF(BQ13>=800,BQ13-80,IF(BQ13>=500,BQ13-50,IF(BQ13>=200,BQ13-20,BQ13)))) | CB13: ✅ 可导入 | CC13: ✓
A14: PPS26330080322 | B14: 畔色榉木柔光双人床 |榉木小灯床 | C14: 榉木柔光床-1.8米-榉木铺板 | D14: PPS2633008032214 | E14: https://img.alicdn.com/imgextra/i3/2215699812811/O1CN011b8ljX1WdUTWEOKNH_!!2215699812811.jpg | F14: 中型 | G14: =Q14/0.4 | H14: =G14*0.75 | I14: =Q14 / (0.855 - 0.02 - 0.006) | J14: =Q14 / (0.87 - 0.02 - 0.006) | K14: =Q14 / (0.9 - 0.02 - 0.006) | L14: =K14-N14 | M14: =L14/K14 | N14: =O14+P14+Q14 | O14: =K14*0.006 | P14: =K14*0.02 | Q14: =SUM(R14:T14) | R14: =IF(F14="大型",700,IF(F14="中型",300,IF(F14="小型",80,0))) | S14: =IF(F14="大型",150,IF(F14="中型",100,IF(F14="小型",0,0))) | T14: =SUM(U14:W14) | U14: 2210 | V14: 150 | W14: =SUM(X14:AS14) | X14: 0 | Y14: 0 | Z14: 100 | AA14: 0 | AB14: 0 | AC14: 0 | AD14: 0 | AE14: 0 | AF14: 0 | AG14: 0 | AH14: 0 | AI14: 0 | AJ14: 0 | AK14: 0 | AL14: 0 | AM14: 0 | AN14: 0 | AO14: 0 | AP14: 0 | AQ14: 0 | AR14: 650 | AS14: 0 | AU14: 外面价格：1.8床铺板打孔+纸箱+整片=23*22+50=556 1.5规格是536，1.2规格是516 | AV14: 69f6f3de6eeaf7000137dca2 | AW14: 榉木柔光床-1.8米-榉木铺板 | AX14: 69f6f3de6eeaf7000137dcac | AY14: =H14 | AZ14: =BB14/(1-BA14) | BA14: 0.15 | BB14: =K14*0.96 | BC14: 1036279566778 | BD14: 待定 | BF14: =H14 | BG14: =BH14/BF14 | BH14: =I14 | BI14: =1-12% | BJ14: =BK14/(BF14-BF14*(1-BI14)) | BK14: =BM14/(1-BL14) | BL14: 0.01 | BM14: =J14 | BN14: =IF(BK14>=1500,BK14-150,IF(BK14>=800,BK14-80,IF(BK14>=500,BK14-50,IF(BK14>=200,BK14-20,BK14)))) | BO14: =1-12% | BP14: =BQ14/(BF14-BF14*(1-BO14)) | BQ14: =BS14/(1-BR14) | BR14: 0 | BS14: =K14 | BT14: =IF(BQ14>=1500,BQ14-150,IF(BQ14>=800,BQ14-80,IF(BQ14>=500,BQ14-50,IF(BQ14>=200,BQ14-20,BQ14)))) | CB14: ✅ 可导入 | CC14: ✓
A15: PPS26330080322 | B15: 畔色榉木柔光双人床 |榉木小灯床 | C15: 榉木柔光床-1.2米-松木铺板 | D15: PPS2633008032215 | E15: https://img.alicdn.com/imgextra/i3/2215699812811/O1CN011b8ljX1WdUTWEOKNH_!!2215699812811.jpg | F15: 中型 | G15: =Q15/0.4 | H15: =G15*0.75 | I15: =Q15 / (0.855 - 0.02 - 0.006) | J15: =Q15 / (0.87 - 0.02 - 0.006) | K15: =Q15 / (0.9 - 0.02 - 0.006) | L15: =K15-N15 | M15: =L15/K15 | N15: =O15+P15+Q15 | O15: =K15*0.006 | P15: =K15*0.02 | Q15: =SUM(R15:T15) | R15: =IF(F15="大型",700,IF(F15="中型",300,IF(F15="小型",80,0))) | S15: =IF(F15="大型",150,IF(F15="中型",100,IF(F15="小型",0,0))) | T15: =SUM(U15:W15) | U15: 1840 | V15: 140 | W15: =SUM(X15:AS15) | X15: 0 | Y15: 0 | Z15: 100 | AA15: 0 | AB15: 0 | AC15: 0 | AD15: 0 | AE15: 0 | AF15: 0 | AG15: 0 | AH15: 0 | AI15: 0 | AJ15: 0 | AK15: 0 | AL15: 0 | AM15: 0 | AN15: 0 | AO15: 0 | AP15: 0 | AQ15: 0 | AR15: 160 | AS15: 0 | AU15: 外面价格：1.8床铺板打孔+纸箱+整片=23*22+50=556 1.5规格是536，1.2规格是516 | AV15: 69f6f3de6eeaf7000137dca2 | AW15: 榉木柔光床-1.2米-松木铺板 | AX15: 69f6f3de6eeaf7000137dcaf | AY15: =H15 | AZ15: =BB15/(1-BA15) | BA15: 0.15 | BB15: =K15*0.96 | BC15: 1036279566778 | BD15: 待定 | BF15: =H15 | BG15: =BH15/BF15 | BH15: =I15 | BI15: =1-12% | BJ15: =BK15/(BF15-BF15*(1-BI15)) | BK15: =BM15/(1-BL15) | BL15: 0.01 | BM15: =J15 | BN15: =IF(BK15>=1500,BK15-150,IF(BK15>=800,BK15-80,IF(BK15>=500,BK15-50,IF(BK15>=200,BK15-20,BK15)))) | BO15: =1-12% | BP15: =BQ15/(BF15-BF15*(1-BO15)) | BQ15: =BS15/(1-BR15) | BR15: 0 | BS15: =K15 | BT15: =IF(BQ15>=1500,BQ15-150,IF(BQ15>=800,BQ15-80,IF(BQ15>=500,BQ15-50,IF(BQ15>=200,BQ15-20,BQ15)))) | CB15: ✅ 可导入 | CC15: ✓
A16: PPS26330080322 | B16: 畔色榉木柔光双人床 |榉木小灯床 | C16: 榉木柔光床-1.35米-松木铺板 | D16: PPS2633008032216 | E16: https://img.alicdn.com/imgextra/i3/2215699812811/O1CN011b8ljX1WdUTWEOKNH_!!2215699812811.jpg | F16: 中型 | G16: =Q16/0.4 | H16: =G16*0.75 | I16: =Q16 / (0.855 - 0.02 - 0.006) | J16: =Q16 / (0.87 - 0.02 - 0.006) | K16: =Q16 / (0.9 - 0.02 - 0.006) | L16: =K16-N16 | M16: =L16/K16 | N16: =O16+P16+Q16 | O16: =K16*0.006 | P16: =K16*0.02 | Q16: =SUM(R16:T16) | R16: =IF(F16="大型",700,IF(F16="中型",300,IF(F16="小型",80,0))) | S16: =IF(F16="大型",150,IF(F16="中型",100,IF(F16="小型",0,0))) | T16: =SUM(U16:W16) | U16: 1870 | V16: 140 | W16: =SUM(X16:AS16) | X16: 0 | Y16: 0 | Z16: 100 | AA16: 0 | AB16: 0 | AC16: 0 | AD16: 0 | AE16: 0 | AF16: 0 | AG16: 0 | AH16: 0 | AI16: 0 | AJ16: 0 | AK16: 0 | AL16: 0 | AM16: 0 | AN16: 0 | AO16: 0 | AP16: 0 | AQ16: 0 | AR16: 180 | AS16: 0 | AU16: 外面价格：1.8床铺板打孔+纸箱+整片=23*22+50=556 1.5规格是536，1.2规格是516 | AV16: 69f6f3de6eeaf7000137dca2 | AW16: 榉木柔光床-1.35米-松木铺板 | AX16: 69f6f3de6eeaf7000137dcb2 | AY16: =H16 | AZ16: =BB16/(1-BA16) | BA16: 0.15 | BB16: =K16*0.96 | BC16: 1036279566778 | BD16: 待定 | BF16: =H16 | BG16: =BH16/BF16 | BH16: =I16 | BI16: =1-12% | BJ16: =BK16/(BF16-BF16*(1-BI16)) | BK16: =BM16/(1-BL16) | BL16: 0.01 | BM16: =J16 | BN16: =IF(BK16>=1500,BK16-150,IF(BK16>=800,BK16-80,IF(BK16>=500,BK16-50,IF(BK16>=200,BK16-20,BK16)))) | BO16: =1-12% | BP16: =BQ16/(BF16-BF16*(1-BO16)) | BQ16: =BS16/(1-BR16) | BR16: 0 | BS16: =K16 | BT16: =IF(BQ16>=1500,BQ16-150,IF(BQ16>=800,BQ16-80,IF(BQ16>=500,BQ16-50,IF(BQ16>=200,BQ16-20,BQ16)))) | CB16: ✅ 可导入 | CC16: ✓
A17: PPS26330080322 | B17: 畔色榉木柔光双人床 |榉木小灯床 | C17: 榉木柔光床-1.5米-松木铺板 | D17: PPS2633008032217 | E17: https://img.alicdn.com/imgextra/i3/2215699812811/O1CN011b8ljX1WdUTWEOKNH_!!2215699812811.jpg | F17: 中型 | G17: =Q17/0.4 | H17: =G17*0.75 | I17: =Q17 / (0.855 - 0.02 - 0.006) | J17: =Q17 / (0.87 - 0.02 - 0.006) | K17: =Q17 / (0.9 - 0.02 - 0.006) | L17: =K17-N17 | M17: =L17/K17 | N17: =O17+P17+Q17 | O17: =K17*0.006 | P17: =K17*0.02 | Q17: =SUM(R17:T17) | R17: =IF(F17="大型",700,IF(F17="中型",300,IF(F17="小型",80,0))) | S17: =IF(F17="大型",150,IF(F17="中型",100,IF(F17="小型",0,0))) | T17: =SUM(U17:W17) | U17: 1920 | V17: 150 | W17: =SUM(X17:AS17) | X17: 0 | Y17: 0 | Z17: 100 | AA17: 0 | AB17: 0 | AC17: 0 | AD17: 0 | AE17: 0 | AF17: 0 | AG17: 0 | AH17: 0 | AI17: 0 | AJ17: 0 | AK17: 0 | AL17: 0 | AM17: 0 | AN17: 0 | AO17: 0 | AP17: 0 | AQ17: 0 | AR17: 180 | AS17: 0 | AU17: 外面价格：1.8床铺板打孔+纸箱+整片=23*22+50=556 1.5规格是536，1.2规格是516 | AV17: 69f6f3de6eeaf7000137dca2 | AW17: 榉木柔光床-1.5米-松木铺板 | AX17: 69f6f3de6eeaf7000137dcb5 | AY17: =H17 | AZ17: =BB17/(1-BA17) | BA17: 0.15 | BB17: =K17*0.96 | BC17: 1036279566778 | BD17: 待定 | BF17: =H17 | BG17: =BH17/BF17 | BH17: =I17 | BI17: =1-12% | BJ17: =BK17/(BF17-BF17*(1-BI17)) | BK17: =BM17/(1-BL17) | BL17: 0.01 | BM17: =J17 | BN17: =IF(BK17>=1500,BK17-150,IF(BK17>=800,BK17-80,IF(BK17>=500,BK17-50,IF(BK17>=200,BK17-20,BK17)))) | BO17: =1-12% | BP17: =BQ17/(BF17-BF17*(1-BO17)) | BQ17: =BS17/(1-BR17) | BR17: 0 | BS17: =K17 | BT17: =IF(BQ17>=1500,BQ17-150,IF(BQ17>=800,BQ17-80,IF(BQ17>=500,BQ17-50,IF(BQ17>=200,BQ17-20,BQ17)))) | CB17: ✅ 可导入 | CC17: ✓
A18: PPS26330080322 | B18: 畔色榉木柔光双人床 |榉木小灯床 | C18: 榉木柔光床-1.8米-松木铺板 | D18: PPS2633008032218 | E18: https://img.alicdn.com/imgextra/i3/2215699812811/O1CN011b8ljX1WdUTWEOKNH_!!2215699812811.jpg | F18: 中型 | G18: =Q18/0.4 | H18: =G18*0.75 | I18: =Q18 / (0.855 - 0.02 - 0.006) | J18: =Q18 / (0.87 - 0.02 - 0.006) | K18: =Q18 / (0.9 - 0.02 - 0.006) | L18: =K18-N18 | M18: =L18/K18 | N18: =O18+P18+Q18 | O18: =K18*0.006 | P18: =K18*0.02 | Q18: =SUM(R18:T18) | R18: =IF(F18="大型",700,IF(F18="中型",300,IF(F18="小型",80,0))) | S18: =IF(F18="大型",150,IF(F18="中型",100,IF(F18="小型",0,0))) | T18: =SUM(U18:W18) | U18: 2000 | V18: 150 | W18: =SUM(X18:AS18) | X18: 0 | Y18: 0 | Z18: 100 | AA18: 0 | AB18: 0 | AC18: 0 | AD18: 0 | AE18: 0 | AF18: 0 | AG18: 0 | AH18: 0 | AI18: 0 | AJ18: 0 | AK18: 0 | AL18: 0 | AM18: 0 | AN18: 0 | AO18: 0 | AP18: 0 | AQ18: 0 | AR18: 200 | AS18: 0 | AU18: 外面价格：1.8床铺板打孔+纸箱+整片=23*22+50=556 1.5规格是536，1.2规格是516 | AV18: 69f6f3de6eeaf7000137dca2 | AW18: 榉木柔光床-1.8米-松木铺板 | AX18: 69f6f3de6eeaf7000137dcb8 | AY18: =H18 | AZ18: =BB18/(1-BA18) | BA18: 0.15 | BB18: =K18*0.96 | BC18: 1036279566778 | BD18: 待定 | BF18: =H18 | BG18: =BH18/BF18 | BH18: =I18 | BI18: =1-12% | BJ18: =BK18/(BF18-BF18*(1-BI18)) | BK18: =BM18/(1-BL18) | BL18: 0.01 | BM18: =J18 | BN18: =IF(BK18>=1500,BK18-150,IF(BK18>=800,BK18-80,IF(BK18>=500,BK18-50,IF(BK18>=200,BK18-20,BK18)))) | BO18: =1-12% | BP18: =BQ18/(BF18-BF18*(1-BO18)) | BQ18: =BS18/(1-BR18) | BR18: 0 | BS18: =K18 | BT18: =IF(BQ18>=1500,BQ18-150,IF(BQ18>=800,BQ18-80,IF(BQ18>=500,BQ18-50,IF(BQ18>=200,BQ18-20,BQ18)))) | CB18: ✅ 可导入 | CC18: ✓
A19: PPS26330080322 | B19: 畔色榉木柔光双人床 |榉木小灯床 | C19: 榉木大靠背床（无灯）-1.2米-榉木铺板 | D19: PPS2633008032219 | E19: https://img.alicdn.com/imgextra/i3/2215699812811/O1CN011b8ljX1WdUTWEOKNH_!!2215699812811.jpg | F19: 中型 | G19: =Q19/0.4 | H19: =G19*0.75 | I19: =Q19 / (0.855 - 0.02 - 0.006) | J19: =Q19 / (0.87 - 0.02 - 0.006) | K19: =Q19 / (0.9 - 0.02 - 0.006) | L19: =K19-N19 | M19: =L19/K19 | N19: =O19+P19+Q19 | O19: =K19*0.006 | P19: =K19*0.02 | Q19: =SUM(R19:T19) | R19: =IF(F19="大型",700,IF(F19="中型",300,IF(F19="小型",80,0))) | S19: =IF(F19="大型",150,IF(F19="中型",100,IF(F19="小型",0,0))) | T19: =SUM(U19:W19) | U19: 2010 | V19: 140 | W19: =SUM(X19:AS19) | X19: 0 | Y19: 0 | Z19: 0 | AA19: 0 | AB19: 0 | AC19: 0 | AD19: 0 | AE19: 0 | AF19: 0 | AG19: 0 | AH19: 0 | AI19: 0 | AJ19: 0 | AK19: 0 | AL19: 0 | AM19: 0 | AN19: 0 | AO19: 0 | AP19: 0 | AQ19: 0 | AR19: 590 | AS19: 0 | AU19: 外面价格：1.8床铺板打孔+纸箱+整片=23*22+50=556 1.5规格是536，1.2规格是516 | AV19: 69f6f3de6eeaf7000137dca2 | AW19: 榉木大靠背床（无灯）-1.2米-榉木铺板 | AX19: 69f6f3de6eeaf7000137dcbb | AY19: =H19 | AZ19: =BB19/(1-BA19) | BA19: 0.15 | BB19: =K19*0.96 | BC19: 1036279566778 | BD19: 待定 | BF19: =H19 | BG19: =BH19/BF19 | BH19: =I19 | BI19: =1-12% | BJ19: =BK19/(BF19-BF19*(1-BI19)) | BK19: =BM19/(1-BL19) | BL19: 0.01 | BM19: =J19 | BN19: =IF(BK19>=1500,BK19-150,IF(BK19>=800,BK19-80,IF(BK19>=500,BK19-50,IF(BK19>=200,BK19-20,BK19)))) | BO19: =1-12% | BP19: =BQ19/(BF19-BF19*(1-BO19)) | BQ19: =BS19/(1-BR19) | BR19: 0 | BS19: =K19 | BT19: =IF(BQ19>=1500,BQ19-150,IF(BQ19>=800,BQ19-80,IF(BQ19>=500,BQ19-50,IF(BQ19>=200,BQ19-20,BQ19)))) | CB19: ✅ 可导入 | CC19: ✓
A20: PPS26330080322 | B20: 畔色榉木柔光双人床 |榉木小灯床 | C20: 榉木大靠背床（无灯）-1.35米-榉木铺板 | D20: PPS2633008032220 | E20: https://img.alicdn.com/imgextra/i3/2215699812811/O1CN011b8ljX1WdUTWEOKNH_!!2215699812811.jpg | F20: 中型 | G20: =Q20/0.4 | H20: =G20*0.75 | I20: =Q20 / (0.855 - 0.02 - 0.006) | J20: =Q20 / (0.87 - 0.02 - 0.006) | K20: =Q20 / (0.9 - 0.02 - 0.006) | L20: =K20-N20 | M20: =L20/K20 | N20: =O20+P20+Q20 | O20: =K20*0.006 | P20: =K20*0.02 | Q20: =SUM(R20:T20) | R20: =IF(F20="大型",700,IF(F20="中型",300,IF(F20="小型",80,0))) | S20: =IF(F20="大型",150,IF(F20="中型",100,IF(F20="小型",0,0))) | T20: =SUM(U20:W20) | U20: 2040 | V20: 140 | W20: =SUM(X20:AS20) | X20: 0 | Y20: 0 | Z20: 0 | AA20: 0 | AB20: 0 | AC20: 0 | AD20: 0 | AE20: 0 | AF20: 0 | AG20: 0 | AH20: 0 | AI20: 0 | AJ20: 0 | AK20: 0 | AL20: 0 | AM20: 0 | AN20: 0 | AO20: 0 | AP20: 0 | AQ20: 0 | AR20: 610 | AS20: 0 | AU20: 外面价格：1.8床铺板打孔+纸箱+整片=23*22+50=556 1.5规格是536，1.2规格是516 | AV20: 69f6f3de6eeaf7000137dca2 | AW20: 榉木大靠背床（无灯）-1.35米-榉木铺板 | AX20: 69f6f3de6eeaf7000137dcbe | AY20: =H20 | AZ20: =BB20/(1-BA20) | BA20: 0.15 | BB20: =K20*0.96 | BC20: 1036279566778 | BD20: 待定 | BF20: =H20 | BG20: =BH20/BF20 | BH20: =I20 | BI20: =1-12% | BJ20: =BK20/(BF20-BF20*(1-BI20)) | BK20: =BM20/(1-BL20) | BL20: 0.01 | BM20: =J20 | BN20: =IF(BK20>=1500,BK20-150,IF(BK20>=800,BK20-80,IF(BK20>=500,BK20-50,IF(BK20>=200,BK20-20,BK20)))) | BO20: =1-12% | BP20: =BQ20/(BF20-BF20*(1-BO20)) | BQ20: =BS20/(1-BR20) | BR20: 0 | BS20: =K20 | BT20: =IF(BQ20>=1500,BQ20-150,IF(BQ20>=800,BQ20-80,IF(BQ20>=500,BQ20-50,IF(BQ20>=200,BQ20-20,BQ20)))) | CB20: ✅ 可导入 | CC20: ✓
A21: PPS26330080322 | B21: 畔色榉木柔光双人床 |榉木小灯床 | C21: 榉木大靠背床（无灯）-1.5米-榉木铺板 | D21: PPS2633008032221 | E21: https://img.alicdn.com/imgextra/i3/2215699812811/O1CN011b8ljX1WdUTWEOKNH_!!2215699812811.jpg | F21: 中型 | G21: =Q21/0.4 | H21: =G21*0.75 | I21: =Q21 / (0.855 - 0.02 - 0.006) | J21: =Q21 / (0.87 - 0.02 - 0.006) | K21: =Q21 / (0.9 - 0.02 - 0.006) | L21: =K21-N21 | M21: =L21/K21 | N21: =O21+P21+Q21 | O21: =K21*0.006 | P21: =K21*0.02 | Q21: =SUM(R21:T21) | R21: =IF(F21="大型",700,IF(F21="中型",300,IF(F21="小型",80,0))) | S21: =IF(F21="大型",150,IF(F21="中型",100,IF(F21="小型",0,0))) | T21: =SUM(U21:W21) | U21: 2120 | V21: 150 | W21: =SUM(X21:AS21) | X21: 0 | Y21: 0 | Z21: 0 | AA21: 0 | AB21: 0 | AC21: 0 | AD21: 0 | AE21: 0 | AF21: 0 | AG21: 0 | AH21: 0 | AI21: 0 | AJ21: 0 | AK21: 0 | AL21: 0 | AM21: 0 | AN21: 0 | AO21: 0 | AP21: 0 | AQ21: 0 | AR21: 630 | AS21: 0 | AU21: 外面价格：1.8床铺板打孔+纸箱+整片=23*22+50=556 1.5规格是536，1.2规格是516 | AV21: 69f6f3de6eeaf7000137dca2 | AW21: 榉木大靠背床（无灯）-1.5米-榉木铺板 | AX21: 69f6f3de6eeaf7000137dcc1 | AY21: =H21 | AZ21: =BB21/(1-BA21) | BA21: 0.15 | BB21: =K21*0.96 | BC21: 1036279566778 | BD21: 待定 | BF21: =H21 | BG21: =BH21/BF21 | BH21: =I21 | BI21: =1-12% | BJ21: =BK21/(BF21-BF21*(1-BI21)) | BK21: =BM21/(1-BL21) | BL21: 0.01 | BM21: =J21 | BN21: =IF(BK21>=1500,BK21-150,IF(BK21>=800,BK21-80,IF(BK21>=500,BK21-50,IF(BK21>=200,BK21-20,BK21)))) | BO21: =1-12% | BP21: =BQ21/(BF21-BF21*(1-BO21)) | BQ21: =BS21/(1-BR21) | BR21: 0 | BS21: =K21 | BT21: =IF(BQ21>=1500,BQ21-150,IF(BQ21>=800,BQ21-80,IF(BQ21>=500,BQ21-50,IF(BQ21>=200,BQ21-20,BQ21)))) | CB21: ✅ 可导入 | CC21: ✓
A22: PPS26330080322 | B22: 畔色榉木柔光双人床 |榉木小灯床 | C22: 榉木大靠背床（无灯）-1.8米-榉木铺板 | D22: PPS2633008032222 | E22: https://img.alicdn.com/imgextra/i3/2215699812811/O1CN011b8ljX1WdUTWEOKNH_!!2215699812811.jpg | F22: 中型 | G22: =Q22/0.4 | H22: =G22*0.75 | I22: =Q22 / (0.855 - 0.02 - 0.006) | J22: =Q22 / (0.87 - 0.02 - 0.006) | K22: =Q22 / (0.9 - 0.02 - 0.006) | L22: =K22-N22 | M22: =L22/K22 | N22: =O22+P22+Q22 | O22: =K22*0.006 | P22: =K22*0.02 | Q22: =SUM(R22:T22) | R22: =IF(F22="大型",700,IF(F22="中型",300,IF(F22="小型",80,0))) | S22: =IF(F22="大型",150,IF(F22="中型",100,IF(F22="小型",0,0))) | T22: =SUM(U22:W22) | U22: 2210 | V22: 150 | W22: =SUM(X22:AS22) | X22: 0 | Y22: 0 | Z22: 0 | AA22: 0 | AB22: 0 | AC22: 0 | AD22: 0 | AE22: 0 | AF22: 0 | AG22: 0 | AH22: 0 | AI22: 0 | AJ22: 0 | AK22: 0 | AL22: 0 | AM22: 0 | AN22: 0 | AO22: 0 | AP22: 0 | AQ22: 0 | AR22: 650 | AS22: 0 | AU22: 外面价格：1.8床铺板打孔+纸箱+整片=23*22+50=556 1.5规格是536，1.2规格是516 | AV22: 69f6f3de6eeaf7000137dca2 | AW22: 榉木大靠背床（无灯）-1.8米-榉木铺板 | AX22: 69f6f3de6eeaf7000137dcc4 | AY22: =H22 | AZ22: =BB22/(1-BA22) | BA22: 0.15 | BB22: =K22*0.96 | BC22: 1036279566778 | BD22: 待定 | BF22: =H22 | BG22: =BH22/BF22 | BH22: =I22 | BI22: =1-12% | BJ22: =BK22/(BF22-BF22*(1-BI22)) | BK22: =BM22/(1-BL22) | BL22: 0.01 | BM22: =J22 | BN22: =IF(BK22>=1500,BK22-150,IF(BK22>=800,BK22-80,IF(BK22>=500,BK22-50,IF(BK22>=200,BK22-20,BK22)))) | BO22: =1-12% | BP22: =BQ22/(BF22-BF22*(1-BO22)) | BQ22: =BS22/(1-BR22) | BR22: 0 | BS22: =K22 | BT22: =IF(BQ22>=1500,BQ22-150,IF(BQ22>=800,BQ22-80,IF(BQ22>=500,BQ22-50,IF(BQ22>=200,BQ22-20,BQ22)))) | CB22: ✅ 可导入 | CC22: ✓
A23: PPS26330090325 | B23: 畔色榉木编织双人床 |榉木藤编床 | C23: 榉木编织床-1.2米-榉木铺板 | D23: PPS2633009032511 | E23: 暂无 | F23: 中型 | G23: =Q23/0.4 | H23: =G23*0.75 | I23: =Q23 / (0.855 - 0.02 - 0.006) | J23: =Q23 / (0.87 - 0.02 - 0.006) | K23: =Q23 / (0.9 - 0.02 - 0.006) | L23: =K23-N23 | M23: =L23/K23 | N23: =O23+P23+Q23 | O23: =K23*0.006 | P23: =K23*0.02 | Q23: =SUM(R23:T23) | R23: =IF(F23="大型",700,IF(F23="中型",300,IF(F23="小型",80,0))) | S23: =IF(F23="大型",150,IF(F23="中型",100,IF(F23="小型",0,0))) | T23: =SUM(U23:W23) | U23: 0 | V23: 140 | W23: =SUM(X23:AS23) | X23: 0 | Y23: 0 | Z23: 0 | AA23: 0 | AB23: 0 | AC23: 0 | AD23: 0 | AE23: 0 | AF23: 0 | AG23: 0 | AH23: 0 | AI23: 0 | AJ23: 0 | AK23: 0 | AL23: 0 | AM23: 0 | AN23: 0 | AO23: 0 | AP23: 0 | AQ23: 0 | AR23: 590 | AS23: 0 | AV23: / | AW23: / | AX23: / | AY23: =H23 | AZ23: =BB23/(1-BA23) | BA23: 0.15 | BB23: =K23*0.96 | BC23: 暂无 | BD23: 待定 | BF23: =H23 | BG23: =BH23/BF23 | BH23: =I23 | BI23: =1-12% | BJ23: =BK23/(BF23-BF23*(1-BI23)) | BK23: =BM23/(1-BL23) | BL23: 0.01 | BM23: =J23 | BN23: =IF(BK23>=1500,BK23-150,IF(BK23>=800,BK23-80,IF(BK23>=500,BK23-50,IF(BK23>=200,BK23-20,BK23)))) | BO23: =1-12% | BP23: =BQ23/(BF23-BF23*(1-BO23)) | BQ23: =BS23/(1-BR23) | BR23: 0 | BS23: =K23 | BT23: =IF(BQ23>=1500,BQ23-150,IF(BQ23>=800,BQ23-80,IF(BQ23>=500,BQ23-50,IF(BQ23>=200,BQ23-20,BQ23)))) | CB23: ✅ 可导入 | CC23: 木作成本原为文字，已置0待补
A24: PPS26330090325 | B24: 畔色榉木编织双人床 |榉木藤编床 | C24: 榉木编织床-1.35米-榉木铺板 | D24: PPS2633009032512 | E24: 暂无 | F24: 中型 | G24: =Q24/0.4 | H24: =G24*0.75 | I24: =Q24 / (0.855 - 0.02 - 0.006) | J24: =Q24 / (0.87 - 0.02 - 0.006) | K24: =Q24 / (0.9 - 0.02 - 0.006) | L24: =K24-N24 | M24: =L24/K24 | N24: =O24+P24+Q24 | O24: =K24*0.006 | P24: =K24*0.02 | Q24: =SUM(R24:T24) | R24: =IF(F24="大型",700,IF(F24="中型",300,IF(F24="小型",80,0))) | S24: =IF(F24="大型",150,IF(F24="中型",100,IF(F24="小型",0,0))) | T24: =SUM(U24:W24) | U24: 0 | V24: 140 | W24: =SUM(X24:AS24) | X24: 0 | Y24: 0 | Z24: 0 | AA24: 0 | AB24: 0 | AC24: 0 | AD24: 0 | AE24: 0 | AF24: 0 | AG24: 0 | AH24: 0 | AI24: 0 | AJ24: 0 | AK24: 0 | AL24: 0 | AM24: 0 | AN24: 0 | AO24: 0 | AP24: 0 | AQ24: 0 | AR24: 610 | AS24: 0 | AV24: / | AW24: / | AX24: / | AY24: =H24 | AZ24: =BB24/(1-BA24) | BA24: 0.15 | BB24: =K24*0.96 | BC24: 暂无 | BD24: 待定 | BF24: =H24 | BG24: =BH24/BF24 | BH24: =I24 | BI24: =1-12% | BJ24: =BK24/(BF24-BF24*(1-BI24)) | BK24: =BM24/(1-BL24) | BL24: 0.01 | BM24: =J24 | BN24: =IF(BK24>=1500,BK24-150,IF(BK24>=800,BK24-80,IF(BK24>=500,BK24-50,IF(BK24>=200,BK24-20,BK24)))) | BO24: =1-12% | BP24: =BQ24/(BF24-BF24*(1-BO24)) | BQ24: =BS24/(1-BR24) | BR24: 0 | BS24: =K24 | BT24: =IF(BQ24>=1500,BQ24-150,IF(BQ24>=800,BQ24-80,IF(BQ24>=500,BQ24-50,IF(BQ24>=200,BQ24-20,BQ24)))) | CB24: ✅ 可导入 | CC24: 木作成本原为文字，已置0待补
