Workbook

Sheet ⚙️ 参数设置
A1: 畔色报价系统 — 参数设置 & 物料单价库 | G1: 系统参数（黄色格可修改）
A2: 成本分组 | B2: 材料/物料名称 | C2: 单位 | D2: 单价（¥） | E2: 备注 | G2: 参数名称 | H2: 当前值 | I2: 说明
A3: 木材成本 | B3: 黑胡桃木-2.2cm厚度 | C3: 平方米 | D3: 500 | G3: 工厂利润系数 | H3: 0.25 | I3: 木材+人工成本 × (1+系数) = 工厂报价给畔色
B4: 白橡木-2.2cm厚度 | C4: 平方米 | D4: 300 | G4: 畔色利润系数 | H4: 0.15 | I4: 高定模式：畔色总成本 ÷ (1-系数) = 最终报价
B5: 樱桃木-2.2cm厚度 | C5: 平方米 | D5: 300 | G5: 人工占出厂比例 | H5: 0.3 | I5: 轻定制追加部分人工费估算比例
B6: 白蜡木-2.2cm厚度 | C6: 平方米 | D6: 300
B7: 红橡木-2.2cm厚度 | C7: 平方米 | D7: 240 | G7: 打包费-小型 | H7: 100 | I7: 床头柜 / 组合柜 / 小推车 / 餐凳 / 衣帽架
B8: 榉木-2.2cm厚度 | C8: 平方米 | D8: 240 | G8: 打包费-中型 | H8: 200 | I8: 床 / 梳妆台 / 斗柜 / 镜子 / 电视柜 / 茶几 / 餐桌 / 升降桌
B9: 实木多层板1.8cm厚度 | C9: 平方米 | D9: 220 | G9: 打包费-大型 | H9: 400 | I9: 餐边柜 / 岛台 / 书柜 / 书桌 / 鞋柜
B10: 樱桃木-2.8cm厚度 | C10: 平方米 | D10: 520 | G10: 运费-小型 | H10: 80
A11: 配件材料成本 | B11: 12mm 普通岩板 | C11: 平方米 | D11: 200 | G11: 运费-中型 | H11: 100
B12: 12mm 洞石岩板 | C12: 平方米 | D12: 400 | G12: 运费-大型 | H12: 300
B13: 9mm 洞石下挂岩板 | C13: 平方米 | D13: 660 | E13: 不准确，2米以上的价格更贵；岩板按照具体尺寸计算 | G13: 安装费-小型 | H13: 50
B14: 亚克力洞洞板 | C14: 平方米 | D14: 300 | G14: 安装费-中型 | H14: 100
B15: 金属洞洞板 | C15: 平方米 | D15: 250 | G15: 安装费-大型 | H15: 150
B16: MDF纤维洞洞板 | C16: 平方米 | D16: 250
B17: 洞石背板 | C17: 平方米 | D17: 95 | G17: 榉木单价(参考) | H17: 240 | I17: 用于计算换材差价，如有变动请修改
B18: 软木板 | C18: 平方米 | D18: 86 | G18: 黑胡桃单价(参考) | H18: 500 | I18: 用于计算换材差价，如有变动请修改
B19: 电力轨道-带挂架 | C19: 米 | D19: 368 | E19: 挂架款1米均价；含2插座；标配3米长2.5平电线 | G19: 樱桃木单价(参考) | H19: 300 | I19: 用于计算换材差价，如有变动请修改
B20: 电力轨道-普通款 | C20: 米 | D20: 625 | E20: 普通款1米均价；含2插座；标配3米长2.5平电线
B21: 灯带 | C21: 米 | D21: 50 | E21: 按照100一根给客户算
B22: 层板灯 | C22: 米 | D22: 25 | E22: 不含感应按钮和变压器
B23: 超白玻璃 | C23: 平方米 | D23: 250 | E23: 1张顶柜玻璃40-50块左右
B24: 压花玻璃 | C24: 平方米 | D24: 250 | E24: 1张顶柜玻璃40-50块左右
B25: 钢化玻璃 | C25: 平方米 | D25: 250 | E25: 1张顶柜玻璃40-50块左右
B26: 瓷白玻璃 | C26: 平方米 | D26: 263 | E26: 实际是亚克力?
B27: 磁吸瓷白玻璃 | C27: 平方米 | D27: 309 | E27: 超自磁吸玻璃
B28: 美耐板 | C28: 平方米 | D28: 80 | E28: 1.22*2.44m 1mm厚度；买就是一整张135
B29: 铝合金轨道槽 | C29: 米 | D29: 25 | E29: 不含堵头，2米以上长度48一根，且超长需要加物流费
B30: 抽屉轨道 | C30: 付 | D30: 22 | E30: 16寸阻尼款（其他会不同）
B31: 桌下理线架 | C31: 个 | D31: 72
B32: 五金件 | C32: 组 | D32: 100
B33: 镜子 | C33: 平方米 | D33: 200
B34: 榉木床铺板 | C34: 张 | D34: 600
B35: 镜面金属板 | C35: 平方米 | D35: 200
B36: 旋转金属底座 | C36: 个 | D36: 400
B37: 亚克力条 | C37: 1米 | D37: 40
B38: 金属把手 | C38: 1个 | D38: 30
B39: 移动金属轮 | C39: 1个 | D39: 40
B40: 金属轨道 | C40: 1米 | D40: 25
...

Sheet ① 轻定制报价
A1: 畔色 轻定制报价表 — 在标准款基础上调整尺寸/材质，自动计算售价
A2: 产品信息 | H2: 标准款成本（等工厂报价填H/I列） | L2: 四档利润率（黄色可改，每产品独立） | P2: 四档售价（自动计算） | T2: 四档实际毛利率（自动） | X2: 轻定制—尺寸调整单价（每±1cm 或 每㎡ 的加减金额） | AF2: 轻定制—换主材差价（手动填，正数=加价，负数=减价） | AH2: 备注
A3: 产品编码 | B3: 类目 | C3: 产品名称 | D3: SKU | E3: 主材 | F3: 辅材 | G3: 尺寸明细 | H3: 出厂价 (工厂报价) | I3: 木作成本 (纯材料) | J3: 木材占 木作比 | K3: 畔色 总成本 | L3: 日常价 利润率 | M3: 小促价 利润率 | N3: 中促价 利润率 | O3: 大促价 利润率 | P3: 日常价 (自动) | Q3: 小促价 (自动) | R3: 中促价 (自动) | S3: 大促价 (自动) | T3: 日常 毛利率 | U3: 小促 毛利率 | V3: 中促 毛利率 | W3: 大促 毛利率 | X3: 长度 每±1cm | Y3: 宽/深 每±1cm | Z3: 高度 每±1cm | AA3: 顶柜高 每±1cm | AB3: 立收高 每±1cm | AC3: 下柜深 每±1cm | AD3: 追加隔板 每㎡ | AE3: 包装物流 加10cm↑ | AF3: 改榉木 差价¥ | AG3: 改黑胡桃 差价¥ | AH3: 备注
A4: 2633007032099 | B4: 卧室-床 | C4: 畔色榉木无边床 |榉木金属腿床 | D4: 榉木无边床-1.2米-榉木铺板 | E4: 未知 | F4: 未知 | G4: 未知 | H4: 0 | I4: 0 | J4: 0.5 | K4: =IFERROR(H4,0) | L4: 0.4676 | M4: 0.2188 | N4: 0.2015 | O4: 0.1833 | P4: =IFERROR(IF(K4=0,"待填成本",ROUND(K4/(1-L4),0)),"" ) | Q4: =IFERROR(IF(K4=0,"待填成本",ROUND(K4/(1-M4),0)),"" ) | R4: =IFERROR(IF(K4=0,"待填成本",ROUND(K4/(1-N4),0)),"" ) | S4: =IFERROR(IF(K4=0,"待填成本",ROUND(K4/(1-O4),0)),"" ) | T4: =IFERROR(IF(K4=0,"",(P4-K4)/P4),"" ) | U4: =IFERROR(IF(K4=0,"",(Q4-K4)/Q4),"" ) | V4: =IFERROR(IF(K4=0,"",(R4-K4)/R4),"" ) | W4: =IFERROR(IF(K4=0,"",(S4-K4)/S4),"" )
A5: 2633007032099 | B5: 卧室-床 | C5: 畔色榉木无边床 |榉木金属腿床 | D5: 榉木无边床-1.35米-榉木铺板 | E5: 未知 | F5: 未知 | G5: 未知 | H5: 0 | I5: 0 | J5: 0.5 | K5: =IFERROR(H5,0) | L5: 0.4676 | M5: 0.2188 | N5: 0.2015 | O5: 0.1833 | P5: =IFERROR(IF(K5=0,"待填成本",ROUND(K5/(1-L5),0)),"" ) | Q5: =IFERROR(IF(K5=0,"待填成本",ROUND(K5/(1-M5),0)),"" ) | R5: =IFERROR(IF(K5=0,"待填成本",ROUND(K5/(1-N5),0)),"" ) | S5: =IFERROR(IF(K5=0,"待填成本",ROUND(K5/(1-O5),0)),"" ) | T5: =IFERROR(IF(K5=0,"",(P5-K5)/P5),"" ) | U5: =IFERROR(IF(K5=0,"",(Q5-K5)/Q5),"" ) | V5: =IFERROR(IF(K5=0,"",(R5-K5)/R5),"" ) | W5: =IFERROR(IF(K5=0,"",(S5-K5)/S5),"" )
A6: 2633007032099 | B6: 卧室-床 | C6: 畔色榉木无边床 |榉木金属腿床 | D6: 榉木无边床-1.5米-榉木铺板 | E6: 未知 | F6: 未知 | G6: 未知 | H6: 0 | I6: 0 | J6: 0.5 | K6: =IFERROR(H6,0) | L6: 0.4676 | M6: 0.2188 | N6: 0.2015 | O6: 0.1833 | P6: =IFERROR(IF(K6=0,"待填成本",ROUND(K6/(1-L6),0)),"" ) | Q6: =IFERROR(IF(K6=0,"待填成本",ROUND(K6/(1-M6),0)),"" ) | R6: =IFERROR(IF(K6=0,"待填成本",ROUND(K6/(1-N6),0)),"" ) | S6: =IFERROR(IF(K6=0,"待填成本",ROUND(K6/(1-O6),0)),"" ) | T6: =IFERROR(IF(K6=0,"",(P6-K6)/P6),"" ) | U6: =IFERROR(IF(K6=0,"",(Q6-K6)/Q6),"" ) | V6: =IFERROR(IF(K6=0,"",(R6-K6)/R6),"" ) | W6: =IFERROR(IF(K6=0,"",(S6-K6)/S6),"" )
A7: 2633007032099 | B7: 卧室-床 | C7: 畔色榉木无边床 |榉木金属腿床 | D7: 榉木无边床-1.8米-榉木铺板 | E7: 未知 | F7: 未知 | G7: 未知 | H7: 0 | I7: 0 | J7: 0.5 | K7: =IFERROR(H7,0) | L7: 0.4676 | M7: 0.2188 | N7: 0.2015 | O7: 0.1833 | P7: =IFERROR(IF(K7=0,"待填成本",ROUND(K7/(1-L7),0)),"" ) | Q7: =IFERROR(IF(K7=0,"待填成本",ROUND(K7/(1-M7),0)),"" ) | R7: =IFERROR(IF(K7=0,"待填成本",ROUND(K7/(1-N7),0)),"" ) | S7: =IFERROR(IF(K7=0,"待填成本",ROUND(K7/(1-O7),0)),"" ) | T7: =IFERROR(IF(K7=0,"",(P7-K7)/P7),"" ) | U7: =IFERROR(IF(K7=0,"",(Q7-K7)/Q7),"" ) | V7: =IFERROR(IF(K7=0,"",(R7-K7)/R7),"" ) | W7: =IFERROR(IF(K7=0,"",(S7-K7)/S7),"" )
A8: 2633007032099 | B8: 卧室-床 | C8: 畔色榉木无边床 |榉木金属腿床 | D8: 榉木无边床-1.2米-松木铺板 | E8: 未知 | F8: 未知 | G8: 未知 | H8: 0 | I8: 0 | J8: 0.5 | K8: =IFERROR(H8,0) | L8: 0.4676 | M8: 0.2188 | N8: 0.2015 | O8: 0.1833 | P8: =IFERROR(IF(K8=0,"待填成本",ROUND(K8/(1-L8),0)),"" ) | Q8: =IFERROR(IF(K8=0,"待填成本",ROUND(K8/(1-M8),0)),"" ) | R8: =IFERROR(IF(K8=0,"待填成本",ROUND(K8/(1-N8),0)),"" ) | S8: =IFERROR(IF(K8=0,"待填成本",ROUND(K8/(1-O8),0)),"" ) | T8: =IFERROR(IF(K8=0,"",(P8-K8)/P8),"" ) | U8: =IFERROR(IF(K8=0,"",(Q8-K8)/Q8),"" ) | V8: =IFERROR(IF(K8=0,"",(R8-K8)/R8),"" ) | W8: =IFERROR(IF(K8=0,"",(S8-K8)/S8),"" )
A9: 2633007032099 | B9: 卧室-床 | C9: 畔色榉木无边床 |榉木金属腿床 | D9: 榉木无边床-1.35米-松木铺板 | E9: 未知 | F9: 未知 | G9: 未知 | H9: 0 | I9: 0 | J9: 0.5 | K9: =IFERROR(H9,0) | L9: 0.4676 | M9: 0.2188 | N9: 0.2015 | O9: 0.1833 | P9: =IFERROR(IF(K9=0,"待填成本",ROUND(K9/(1-L9),0)),"" ) | Q9: =IFERROR(IF(K9=0,"待填成本",ROUND(K9/(1-M9),0)),"" ) | R9: =IFERROR(IF(K9=0,"待填成本",ROUND(K9/(1-N9),0)),"" ) | S9: =IFERROR(IF(K9=0,"待填成本",ROUND(K9/(1-O9),0)),"" ) | T9: =IFERROR(IF(K9=0,"",(P9-K9)/P9),"" ) | U9: =IFERROR(IF(K9=0,"",(Q9-K9)/Q9),"" ) | V9: =IFERROR(IF(K9=0,"",(R9-K9)/R9),"" ) | W9: =IFERROR(IF(K9=0,"",(S9-K9)/S9),"" )
A10: 2633007032099 | B10: 卧室-床 | C10: 畔色榉木无边床 |榉木金属腿床 | D10: 榉木无边床-1.5米-松木铺板 | E10: 未知 | F10: 未知 | G10: 未知 | H10: 0 | I10: 0 | J10: 0.5 | K10: =IFERROR(H10,0) | L10: 0.4676 | M10: 0.2188 | N10: 0.2015 | O10: 0.1833 | P10: =IFERROR(IF(K10=0,"待填成本",ROUND(K10/(1-L10),0)),"" ) | Q10: =IFERROR(IF(K10=0,"待填成本",ROUND(K10/(1-M10),0)),"" ) | R10: =IFERROR(IF(K10=0,"待填成本",ROUND(K10/(1-N10),0)),"" ) | S10: =IFERROR(IF(K10=0,"待填成本",ROUND(K10/(1-O10),0)),"" ) | T10: =IFERROR(IF(K10=0,"",(P10-K10)/P10),"" ) | U10: =IFERROR(IF(K10=0,"",(Q10-K10)/Q10),"" ) | V10: =IFERROR(IF(K10=0,"",(R10-K10)/R10),"" ) | W10: =IFERROR(IF(K10=0,"",(S10-K10)/S10),"" )
A11: 2633007032099 | B11: 卧室-床 | C11: 畔色榉木无边床 |榉木金属腿床 | D11: 榉木无边床-1.8米-松木铺板 | E11: 未知 | F11: 未知 | G11: 未知 | H11: 0 | I11: 0 | J11: 0.5 | K11: =IFERROR(H11,0) | L11: 0.4676 | M11: 0.2188 | N11: 0.2015 | O11: 0.1833 | P11: =IFERROR(IF(K11=0,"待填成本",ROUND(K11/(1-L11),0)),"" ) | Q11: =IFERROR(IF(K11=0,"待填成本",ROUND(K11/(1-M11),0)),"" ) | R11: =IFERROR(IF(K11=0,"待填成本",ROUND(K11/(1-N11),0)),"" ) | S11: =IFERROR(IF(K11=0,"待填成本",ROUND(K11/(1-O11),0)),"" ) | T11: =IFERROR(IF(K11=0,"",(P11-K11)/P11),"" ) | U11: =IFERROR(IF(K11=0,"",(Q11-K11)/Q11),"" ) | V11: =IFERROR(IF(K11=0,"",(R11-K11)/R11),"" ) | W11: =IFERROR(IF(K11=0,"",(S11-K11)/S11),"" )
A12: 2633008032299 | B12: 卧室-床 | C12: 畔色榉木柔光双人床 |榉木小灯床 | D12: 榉木柔光床-1.2米-榉木铺板 | E12: 未知 | F12: 未知 | G12: 未知 | H12: 0 | I12: 0 | J12: 0.5 | K12: =IFERROR(H12,0) | L12: 0.4676 | M12: 0.2188 | N12: 0.2015 | O12: 0.1833 | P12: =IFERROR(IF(K12=0,"待填成本",ROUND(K12/(1-L12),0)),"" ) | Q12: =IFERROR(IF(K12=0,"待填成本",ROUND(K12/(1-M12),0)),"" ) | R12: =IFERROR(IF(K12=0,"待填成本",ROUND(K12/(1-N12),0)),"" ) | S12: =IFERROR(IF(K12=0,"待填成本",ROUND(K12/(1-O12),0)),"" ) | T12: =IFERROR(IF(K12=0,"",(P12-K12)/P12),"" ) | U12: =IFERROR(IF(K12=0,"",(Q12-K12)/Q12),"" ) | V12: =IFERROR(IF(K12=0,"",(R12-K12)/R12),"" ) | W12: =IFERROR(IF(K12=0,"",(S12-K12)/S12),"" )
A13: 2633008032299 | B13: 卧室-床 | C13: 畔色榉木柔光双人床 |榉木小灯床 | D13: 榉木柔光床-1.35米-榉木铺板 | E13: 未知 | F13: 未知 | G13: 未知 | H13: 0 | I13: 0 | J13: 0.5 | K13: =IFERROR(H13,0) | L13: 0.4676 | M13: 0.2188 | N13: 0.2015 | O13: 0.1833 | P13: =IFERROR(IF(K13=0,"待填成本",ROUND(K13/(1-L13),0)),"" ) | Q13: =IFERROR(IF(K13=0,"待填成本",ROUND(K13/(1-M13),0)),"" ) | R13: =IFERROR(IF(K13=0,"待填成本",ROUND(K13/(1-N13),0)),"" ) | S13: =IFERROR(IF(K13=0,"待填成本",ROUND(K13/(1-O13),0)),"" ) | T13: =IFERROR(IF(K13=0,"",(P13-K13)/P13),"" ) | U13: =IFERROR(IF(K13=0,"",(Q13-K13)/Q13),"" ) | V13: =IFERROR(IF(K13=0,"",(R13-K13)/R13),"" ) | W13: =IFERROR(IF(K13=0,"",(S13-K13)/S13),"" )
A14: 2633008032299 | B14: 卧室-床 | C14: 畔色榉木柔光双人床 |榉木小灯床 | D14: 榉木柔光床-1.5米-榉木铺板 | E14: 未知 | F14: 未知 | G14: 未知 | H14: 0 | I14: 0 | J14: 0.5 | K14: =IFERROR(H14,0) | L14: 0.4676 | M14: 0.2188 | N14: 0.2015 | O14: 0.1833 | P14: =IFERROR(IF(K14=0,"待填成本",ROUND(K14/(1-L14),0)),"" ) | Q14: =IFERROR(IF(K14=0,"待填成本",ROUND(K14/(1-M14),0)),"" ) | R14: =IFERROR(IF(K14=0,"待填成本",ROUND(K14/(1-N14),0)),"" ) | S14: =IFERROR(IF(K14=0,"待填成本",ROUND(K14/(1-O14),0)),"" ) | T14: =IFERROR(IF(K14=0,"",(P14-K14)/P14),"" ) | U14: =IFERROR(IF(K14=0,"",(Q14-K14)/Q14),"" ) | V14: =IFERROR(IF(K14=0,"",(R14-K14)/R14),"" ) | W14: =IFERROR(IF(K14=0,"",(S14-K14)/S14),"" )
A15: 2633008032299 | B15: 卧室-床 | C15: 畔色榉木柔光双人床 |榉木小灯床 | D15: 榉木柔光床-1.8米-榉木铺板 | E15: 未知 | F15: 未知 | G15: 未知 | H15: 0 | I15: 0 | J15: 0.5 | K15: =IFERROR(H15,0) | L15: 0.4676 | M15: 0.2188 | N15: 0.2015 | O15: 0.1833 | P15: =IFERROR(IF(K15=0,"待填成本",ROUND(K15/(1-L15),0)),"" ) | Q15: =IFERROR(IF(K15=0,"待填成本",ROUND(K15/(1-M15),0)),"" ) | R15: =IFERROR(IF(K15=0,"待填成本",ROUND(K15/(1-N15),0)),"" ) | S15: =IFERROR(IF(K15=0,"待填成本",ROUND(K15/(1-O15),0)),"" ) | T15: =IFERROR(IF(K15=0,"",(P15-K15)/P15),"" ) | U15: =IFERROR(IF(K15=0,"",(Q15-K15)/Q15),"" ) | V15: =IFERROR(IF(K15=0,"",(R15-K15)/R15),"" ) | W15: =IFERROR(IF(K15=0,"",(S15-K15)/S15),"" )
... A73: 2638004022599 | B73: 卧室-床头柜 | C73: 畔色榉木床头柜 |榉木铁板床头柜 | D73: 榉木床头柜-标准 | E73: 未知 | F73: 未知 | G73: 未知 | H73: 0 | I73: 0 | J73: 0.55 | K73: =IFERROR(H73,0) | L73: 0.4785 | M73: 0.2533 | N73: 0.2533 | O73: 0.2533 | P73: =IFERROR(IF(K73=0,"待填成本",ROUND(K73/(1-L73),0)),"" ) | Q73: =IFERROR(IF(K73=0,"待填成本",ROUND(K73/(1-M73),0)),"" ) | R73: =IFERROR(IF(K73=0,"待填成本",ROUND(K73/(1-N73),0)),"" ) | S73: =IFERROR(IF(K73=0,"待填成本",ROUND(K73/(1-O73),0)),"" ) | T73: =IFERROR(IF(K73=0,"",(P73-K73)/P73),"" ) | U73: =IFERROR(IF(K73=0,"",(Q73-K73)/Q73),"" ) | V73: =IFERROR(IF(K73=0,"",(R73-K73)/R73),"" ) | W73: =IFERROR(IF(K73=0,"",(S73-K73)/S73),"" )
A74: 2638005030199 | B74: 卧室-床头柜 | C74: 畔色樱桃木轻盈边柜 |樱桃木玻璃床头柜 |黑色玻璃床头柜 |樱桃木玻璃边柜 | D74: 轻盈边柜-榉木黑-木底座 | E74: 未知 | F74: 未知 | G74: 未知 | H74: 0 | I74: 0 | J74: 0.55 | K74: =IFERROR(H74,0) | L74: 0.4785 | M74: 0.2533 | N74: 0.2533 | O74: 0.2533 | P74: =IFERROR(IF(K74=0,"待填成本",ROUND(K74/(1-L74),0)),"" ) | Q74: =IFERROR(IF(K74=0,"待填成本",ROUND(K74/(1-M74),0)),"" ) | R74: =IFERROR(IF(K74=0,"待填成本",ROUND(K74/(1-N74),0)),"" ) | S74: =IFERROR(IF(K74=0,"待填成本",ROUND(K74/(1-O74),0)),"" ) | T74: =IFERROR(IF(K74=0,"",(P74-K74)/P74),"" ) | U74: =IFERROR(IF(K74=0,"",(Q74-K74)/Q74),"" ) | V74: =IFERROR(IF(K74=0,"",(R74-K74)/R74),"" ) | W74: =IFERROR(IF(K74=0,"",(S74-K74)/S74),"" ) | X74: 20 | Y74: 20
A75: 2638005030199 | B75: 卧室-床头柜 | C75: 畔色樱桃木轻盈边柜 |樱桃木玻璃床头柜 |黑色玻璃床头柜 |樱桃木玻璃边柜 | D75: 轻盈边柜-樱桃木-木底座 | E75: 未知 | F75: 未知 | G75: 未知 | H75: 0 | I75: 0 | J75: 0.55 | K75: =IFERROR(H75,0) | L75: 0.4785 | M75: 0.2533 | N75: 0.2533 | O75: 0.2533 | P75: =IFERROR(IF(K75=0,"待填成本",ROUND(K75/(1-L75),0)),"" ) | Q75: =IFERROR(IF(K75=0,"待填成本",ROUND(K75/(1-M75),0)),"" ) | R75: =IFERROR(IF(K75=0,"待填成本",ROUND(K75/(1-N75),0)),"" ) | S75: =IFERROR(IF(K75=0,"待填成本",ROUND(K75/(1-O75),0)),"" ) | T75: =IFERROR(IF(K75=0,"",(P75-K75)/P75),"" ) | U75: =IFERROR(IF(K75=0,"",(Q75-K75)/Q75),"" ) | V75: =IFERROR(IF(K75=0,"",(R75-K75)/R75),"" ) | W75: =IFERROR(IF(K75=0,"",(S75-K75)/S75),"" ) | X75: 20 | Y75: 20
A76: 2638005030199 | B76: 卧室-床头柜 | C76: 畔色樱桃木轻盈边柜 |樱桃木玻璃床头柜 |黑色玻璃床头柜 |樱桃木玻璃边柜 | D76: 轻盈边柜-黑胡桃木-木底座 | E76: 未知 | F76: 未知 | G76: 未知 | H76: 0 | I76: 0 | J76: 0.55 | K76: =IFERROR(H76,0) | L76: 0.4785 | M76: 0.2533 | N76: 0.2533 | O76: 0.2533 | P76: =IFERROR(IF(K76=0,"待填成本",ROUND(K76/(1-L76),0)),"" ) | Q76: =IFERROR(IF(K76=0,"待填成本",ROUND(K76/(1-M76),0)),"" ) | R76: =IFERROR(IF(K76=0,"待填成本",ROUND(K76/(1-N76),0)),"" ) | S76: =IFERROR(IF(K76=0,"待填成本",ROUND(K76/(1-O76),0)),"" ) | T76: =IFERROR(IF(K76=0,"",(P76-K76)/P76),"" ) | U76: =IFERROR(IF(K76=0,"",(Q76-K76)/Q76),"" ) | V76: =IFERROR(IF(K76=0,"",(R76-K76)/R76),"" ) | W76: =IFERROR(IF(K76=0,"",(S76-K76)/S76),"" ) | X76: 20 | Y76: 20
A77: 2638005030199 | B77: 卧室-床头柜 | C77: 畔色樱桃木轻盈边柜 |樱桃木玻璃床头柜 |黑色玻璃床头柜 |樱桃木玻璃边柜 | D77: 轻盈边柜-榉木黑-玻璃底座 | E77: 未知 | F77: 未知 | G77: 未知 | H77: 0 | I77: 0 | J77: 0.55 | K77: =IFERROR(H77,0) | L77: 0.4785 | M77: 0.2533 | N77: 0.2533 | O77: 0.2533 | P77: =IFERROR(IF(K77=0,"待填成本",ROUND(K77/(1-L77),0)),"" ) | Q77: =IFERROR(IF(K77=0,"待填成本",ROUND(K77/(1-M77),0)),"" ) | R77: =IFERROR(IF(K77=0,"待填成本",ROUND(K77/(1-N77),0)),"" ) | S77: =IFERROR(IF(K77=0,"待填成本",ROUND(K77/(1-O77),0)),"" ) | T77: =IFERROR(IF(K77=0,"",(P77-K77)/P77),"" ) | U77: =IFERROR(IF(K77=0,"",(Q77-K77)/Q77),"" ) | V77: =IFERROR(IF(K77=0,"",(R77-K77)/R77),"" ) | W77: =IFERROR(IF(K77=0,"",(S77-K77)/S77),"" ) | X77: 20 | Y77: 20
A78: 2638005030199 | B78: 卧室-床头柜 | C78: 畔色樱桃木轻盈边柜 |樱桃木玻璃床头柜 |黑色玻璃床头柜 |樱桃木玻璃边柜 | D78: 轻盈边柜-樱桃木-玻璃底座 | E78: 未知 | F78: 未知 | G78: 未知 | H78: 0 | I78: 0 | J78: 0.55 | K78: =IFERROR(H78,0) | L78: 0.4785 | M78: 0.2533 | N78: 0.2533 | O78: 0.2533 | P78: =IFERROR(IF(K78=0,"待填成本",ROUND(K78/(1-L78),0)),"" ) | Q78: =IFERROR(IF(K78=0,"待填成本",ROUND(K78/(1-M78),0)),"" ) | R78: =IFERROR(IF(K78=0,"待填成本",ROUND(K78/(1-N78),0)),"" ) | S78: =IFERROR(IF(K78=0,"待填成本",ROUND(K78/(1-O78),0)),"" ) | T78: =IFERROR(IF(K78=0,"",(P78-K78)/P78),"" ) | U78: =IFERROR(IF(K78=0,"",(Q78-K78)/Q78),"" ) | V78: =IFERROR(IF(K78=0,"",(R78-K78)/R78),"" ) | W78: =IFERROR(IF(K78=0,"",(S78-K78)/S78),"" ) | X78: 20 | Y78: 20
A79: 2638005030199 | B79: 卧室-床头柜 | C79: 畔色樱桃木轻盈边柜 |樱桃木玻璃床头柜 |黑色玻璃床头柜 |樱桃木玻璃边柜 | D79: 轻盈边柜-黑胡桃木-玻璃底座 | E79: 未知 | F79: 未知 | G79: 未知 | H79: 0 | I79: 0 | J79: 0.55 | K79: =IFERROR(H79,0) | L79: 0.4785 | M79: 0.2533 | N79: 0.2533 | O79: 0.2533 | P79: =IFERROR(IF(K79=0,"待填成本",ROUND(K79/(1-L79),0)),"" ) | Q79: =IFERROR(IF(K79=0,"待填成本",ROUND(K79/(1-M79),0)),"" ) | R79: =IFERROR(IF(K79=0,"待填成本",ROUND(K79/(1-N79),0)),"" ) | S79: =IFERROR(IF(K79=0,"待填成本",ROUND(K79/(1-O79),0)),"" ) | T79: =IFERROR(IF(K79=0,"",(P79-K79)/P79),"" ) | U79: =IFERROR(IF(K79=0,"",(Q79-K79)/Q79),"" ) | V79: =IFERROR(IF(K79=0,"",(R79-K79)/R79),"" ) | W79: =IFERROR(IF(K79=0,"",(S79-K79)/S79),"" ) | X79: 20 | Y79: 20
A80: 2638006032099 | B80: 卧室-床头柜 | C80: 畔色黑胡桃木床头柜 |黑胡桃木岩板床头柜 | D80: 黑胡桃木床头柜-岩板台面 | E80: 未知 | F80: 未知 | G80: 未知 | H80: 0 | I80: 0 | J80: 0.55 | K80: =IFERROR(H80,0) | L80: 0.4785 | M80: 0.2533 | N80: 0.2533 | O80: 0.2533 | P80: =IFERROR(IF(K80=0,"待填成本",ROUND(K80/(1-L80),0)),"" ) | Q80: =IFERROR(IF(K80=0,"待填成本",ROUND(K80/(1-M80),0)),"" ) | R80: =IFERROR(IF(K80=0,"待填成本",ROUND(K80/(1-N80),0)),"" ) | S80: =IFERROR(IF(K80=0,"待填成本",ROUND(K80/(1-O80),0)),"" ) | T80: =IFERROR(IF(K80=0,"",(P80-K80)/P80),"" ) | U80: =IFERROR(IF(K80=0,"",(Q80-K80)/Q80),"" ) | V80: =IFERROR(IF(K80=0,"",(R80-K80)/R80),"" ) | W80: =IFERROR(IF(K80=0,"",(S80-K80)/S80),"" ) | X80: 25 | Y80: 25
A81: 2638006032099 | B81: 卧室-床头柜 | C81: 畔色黑胡桃木床头柜 |黑胡桃木岩板床头柜 | D81: 黑胡桃木床头柜-木台面 | E81: 未知 | F81: 未知 | G81: 未知 | H81: 0 | I81: 0 | J81: 0.55 | K81: =IFERROR(H81,0) | L81: 0.4785 | M81: 0.2533 | N81: 0.2533 | O81: 0.2533 | P81: =IFERROR(IF(K81=0,"待填成本",ROUND(K81/(1-L81),0)),"" ) | Q81: =IFERROR(IF(K81=0,"待填成本",ROUND(K81/(1-M81),0)),"" ) | R81: =IFERROR(IF(K81=0,"待填成本",ROUND(K81/(1-N81),0)),"" ) | S81: =IFERROR(IF(K81=0,"待填成本",ROUND(K81/(1-O81),0)),"" ) | T81: =IFERROR(IF(K81=0,"",(P81-K81)/P81),"" ) | U81: =IFERROR(IF(K81=0,"",(Q81-K81)/Q81),"" ) | V81: =IFERROR(IF(K81=0,"",(R81-K81)/R81),"" ) | W81: =IFERROR(IF(K81=0,"",(S81-K81)/S81),"" ) | X81: 20 | Y81: 20
A82: 2525009040199 | B82: 餐厅-柜 | C82: 樱桃木基础餐边柜 |樱桃木AA柱餐边柜 | D82: 基础柜-下柜-2.1米 | E82: 北美进口FAS级樱桃木 | F82: 抽屉围板：实木多层板 台面：12mm岩板 背板：实木多层板（AA柱）/亚克力洞洞板 内部赠送层板：实木多层板 电力轨道：xpower 内嵌电力轨道 顶柜玻璃：灰玻 | G82: 整体长度：2100mm/1800mm/1500mm 整体深度：480mm 整体高度：1980mm 顶柜长度：2100mm/1800mm/1500mm 顶柜深度：300mm 顶柜高度：490mm 立体收纳长度：2100mm/1800mm/1500mm 立体收纳深度：300mm 立体收纳高度：610mm 下柜长度：2100mm/1800mm/1500mm 下柜深度：480mm 下柜高度：880mm | H82: 4061 | I82: 3761 | J82: 0.48 | K82: =IFERROR(H82,0) | L82: 0.4669 | M82: 0.2109 | N82: 0.2009 | O82: 0.1801 | P82: =IFERROR(IF(K82=0,"待填成本",ROUND(K82/(1-L82),0)),"" ) | Q82: =IFERROR(IF(K82=0,"待填成本",ROUND(K82/(1-M82),0)),"" ) | R82: =IFERROR(IF(K82=0,"待填成本",ROUND(K82/(1-N82),0)),"" ) | S82: =IFERROR(IF(K82=0,"待填成本",ROUND(K82/(1-O82),0)),"" ) | T82: =IFERROR(IF(K82=0,"",(P82-K82)/P82),"" ) | U82: =IFERROR(IF(K82=0,"",(Q82-K82)/Q82),"" ) | V82: =IFERROR(IF(K82=0,"",(R82-K82)/R82),"" ) | W82: =IFERROR(IF(K82=0,"",(S82-K82)/S82),"" ) | AC82: 21.2175 | AD82: 300 | AE82: 150
A83: 2525009040199 | B83: 餐厅-柜 | C83: 樱桃木基础餐边柜 |樱桃木AA柱餐边柜 | D83: 基础柜-下柜-2.0米 | E83: 北美进口FAS级樱桃木 | F83: 抽屉围板：实木多层板 台面：12mm岩板 背板：实木多层板（AA柱）/亚克力洞洞板 内部赠送层板：实木多层板 电力轨道：xpower 内嵌电力轨道 顶柜玻璃：灰玻 | G83: 整体长度：2100mm/1800mm/1500mm 整体深度：480mm 整体高度：1980mm 顶柜长度：2100mm/1800mm/1500mm 顶柜深度：300mm 顶柜高度：490mm 立体收纳长度：2100mm/1800mm/1500mm 立体收纳深度：300mm 立体收纳高度：610mm 下柜长度：2100mm/1800mm/1500mm 下柜深度：480mm 下柜高度：880mm | H83: 3964.3333 | I83: 3677.6667 | J83: 0.48 | K83: =IFERROR(H83,0) | L83: 0.4669 | M83: 0.2108 | N83: 0.201 | O83: 0.1803 | P83: =IFERROR(IF(K83=0,"待填成本",ROUND(K83/(1-L83),0)),"" ) | Q83: =IFERROR(IF(K83=0,"待填成本",ROUND(K83/(1-M83),0)),"" ) | R83: =IFERROR(IF(K83=0,"待填成本",ROUND(K83/(1-N83),0)),"" ) | S83: =IFERROR(IF(K83=0,"待填成本",ROUND(K83/(1-O83),0)),"" ) | T83: =IFERROR(IF(K83=0,"",(P83-K83)/P83),"" ) | U83: =IFERROR(IF(K83=0,"",(Q83-K83)/Q83),"" ) | V83: =IFERROR(IF(K83=0,"",(R83-K83)/R83),"" ) | W83: =IFERROR(IF(K83=0,"",(S83-K83)/S83),"" ) | AC83: 20.93 | AD83: 300 | AE83: 150
A84: 2525009040199 | B84: 餐厅-柜 | C84: 樱桃木基础餐边柜 |樱桃木AA柱餐边柜 | D84: 基础柜-下柜-1.9米 | E84: 北美进口FAS级樱桃木 | F84: 抽屉围板：实木多层板 台面：12mm岩板 背板：实木多层板（AA柱）/亚克力洞洞板 内部赠送层板：实木多层板 电力轨道：xpower 内嵌电力轨道 顶柜玻璃：灰玻 | G84: 整体长度：2100mm/1800mm/1500mm 整体深度：480mm 整体高度：1980mm 顶柜长度：2100mm/1800mm/1500mm 顶柜深度：300mm 顶柜高度：490mm 立体收纳长度：2100mm/1800mm/1500mm 立体收纳深度：300mm 立体收纳高度：610mm 下柜长度：2100mm/1800mm/1500mm 下柜深度：480mm 下柜高度：880mm | H84: 3867.6667 | I84: 3594.3333 | J84: 0.48 | K84: =IFERROR(H84,0) | L84: 0.467 | M84: 0.2107 | N84: 0.2012 | O84: 0.1804 | P84: =IFERROR(IF(K84=0,"待填成本",ROUND(K84/(1-L84),0)),"" ) | Q84: =IFERROR(IF(K84=0,"待填成本",ROUND(K84/(1-M84),0)),"" ) | R84: =IFERROR(IF(K84=0,"待填成本",ROUND(K84/(1-N84),0)),"" ) | S84: =IFERROR(IF(K84=0,"待填成本",ROUND(K84/(1-O84),0)),"" ) | T84: =IFERROR(IF(K84=0,"",(P84-K84)/P84),"" ) | U84: =IFERROR(IF(K84=0,"",(Q84-K84)/Q84),"" ) | V84: =IFERROR(IF(K84=0,"",(R84-K84)/R84),"" ) | W84: =IFERROR(IF(K84=0,"",(S84-K84)/S84),"" ) | AC84: 20.6425 | AD84: 300 | AE84: 150
A85: 2525009040199 | B85: 餐厅-柜 | C85: 樱桃木基础餐边柜 |樱桃木AA柱餐边柜 | D85: 基础柜-下柜-1.8米 | E85: 北美进口FAS级樱桃木 | F85: 抽屉围板：实木多层板 台面：12mm岩板 背板：实木多层板（AA柱）/亚克力洞洞板 内部赠送层板：实木多层板 电力轨道：xpower 内嵌电力轨道 顶柜玻璃：灰玻 | G85: 整体长度：2100mm/1800mm/1500mm 整体深度：480mm 整体高度：1980mm 顶柜长度：2100mm/1800mm/1500mm 顶柜深度：300mm 顶柜高度：490mm 立体收纳长度：2100mm/1800mm/1500mm 立体收纳深度：300mm 立体收纳高度：610mm 下柜长度：2100mm/1800mm/1500mm 下柜深度：480mm 下柜高度：880mm | H85: 3771 | I85: 3511 | J85: 0.48 | K85: =IFERROR(H85,0) | L85: 0.4671 | M85: 0.2106 | N85: 0.2013 | O85: 0.1806 | P85: =IFERROR(IF(K85=0,"待填成本",ROUND(K85/(1-L85),0)),"" ) | Q85: =IFERROR(IF(K85=0,"待填成本",ROUND(K85/(1-M85),0)),"" ) | R85: =IFERROR(IF(K85=0,"待填成本",ROUND(K85/(1-N85),0)),"" ) | S85: =IFERROR(IF(K85=0,"待填成本",ROUND(K85/(1-O85),0)),"" ) | T85: =IFERROR(IF(K85=0,"",(P85-K85)/P85),"" ) | U85: =IFERROR(IF(K85=0,"",(Q85-K85)/Q85),"" ) | V85: =IFERROR(IF(K85=0,"",(R85-K85)/R85),"" ) | W85: =IFERROR(IF(K85=0,"",(S85-K85)/S85),"" ) | AC85: 20.355 | AD85: 300 | AE85: 150
A86: 2525009040199 | B86: 餐厅-柜 | C86: 樱桃木基础餐边柜 |樱桃木AA柱餐边柜 | D86: 基础柜-下柜-1.7米 | E86: 北美进口FAS级樱桃木 | F86: 抽屉围板：实木多层板 台面：12mm岩板 背板：实木多层板（AA柱）/亚克力洞洞板 内部赠送层板：实木多层板 电力轨道：xpower 内嵌电力轨道 顶柜玻璃：灰玻 | G86: 整体长度：2100mm/1800mm/1500mm 整体深度：480mm 整体高度：1980mm 顶柜长度：2100mm/1800mm/1500mm 顶柜深度：300mm 顶柜高度：490mm 立体收纳长度：2100mm/1800mm/1500mm 立体收纳深度：300mm 立体收纳高度：610mm 下柜长度：2100mm/1800mm/1500mm 下柜深度：480mm 下柜高度：880mm | H86: 3681 | I86: 3427.6667 | J86: 0.48 | K86: =IFERROR(H86,0) | L86: 0.467 | M86: 0.2106 | N86: 0.2012 | O86: 0.1805 | P86: =IFERROR(IF(K86=0,"待填成本",ROUND(K86/(1-L86),0)),"" ) | Q86: =IFERROR(IF(K86=0,"待填成本",ROUND(K86/(1-M86),0)),"" ) | R86: =IFERROR(IF(K86=0,"待填成本",ROUND(K86/(1-N86),0)),"" ) | S86: =IFERROR(IF(K86=0,"待填成本",ROUND(K86/(1-O86),0)),"" ) | T86: =IFERROR(IF(K86=0,"",(P86-K86)/P86),"" ) | U86: =IFERROR(IF(K86=0,"",(Q86-K86)/Q86),"" ) | V86: =IFERROR(IF(K86=0,"",(R86-K86)/R86),"" ) | W86: =IFERROR(IF(K86=0,"",(S86-K86)/S86),"" ) | AC86: 20.0675 | AD86: 300 | AE86: 150
A87: 2525009040199 | B87: 餐厅-柜 | C87: 樱桃木基础餐边柜 |樱桃木AA柱餐边柜 | D87: 基础柜-下柜-1.6米 | E87: 北美进口FAS级樱桃木 | F87: 抽屉围板：实木多层板 台面：12mm岩板 背板：实木多层板（AA柱）/亚克力洞洞板 内部赠送层板：实木多层板 电力轨道：xpower 内嵌电力轨道 顶柜玻璃：灰玻 | G87: 整体长度：2100mm/1800mm/1500mm 整体深度：480mm 整体高度：1980mm 顶柜长度：2100mm/1800mm/1500mm 顶柜深度：300mm 顶柜高度：490mm 立体收纳长度：2100mm/1800mm/1500mm 立体收纳深度：300mm 立体收纳高度：610mm 下柜长度：2100mm/1800mm/1500mm 下柜深度：480mm 下柜高度：880mm | H87: 3591 | I87: 3344.3333 | J87: 0.48 | K87: =IFERROR(H87,0) | L87: 0.4669 | M87: 0.2107 | N87: 0.201 | O87: 0.1804 | P87: =IFERROR(IF(K87=0,"待填成本",ROUND(K87/(1-L87),0)),"" ) | Q87: =IFERROR(IF(K87=0,"待填成本",ROUND(K87/(1-M87),0)),"" ) | R87: =IFERROR(IF(K87=0,"待填成本",ROUND(K87/(1-N87),0)),"" ) | S87: =IFERROR(IF(K87=0,"待填成本",ROUND(K87/(1-O87),0)),"" ) | T87: =IFERROR(IF(K87=0,"",(P87-K87)/P87),"" ) | U87: =IFERROR(IF(K87=0,"",(Q87-K87)/Q87),"" ) | V87: =IFERROR(IF(K87=0,"",(R87-K87)/R87),"" ) | W87: =IFERROR(IF(K87=0,"",(S87-K87)/S87),"" ) | AC87: 19.78 | AD87: 300 | AE87: 150
A88: 2525009040199 | B88: 餐厅-柜 | C88: 樱桃木基础餐边柜 |樱桃木AA柱餐边柜 | D88: 基础柜-下柜-1.5米 | E88: 北美进口FAS级樱桃木 | F88: 抽屉围板：实木多层板 台面：12mm岩板 背板：实木多层板（AA柱）/亚克力洞洞板 内部赠送层板：实木多层板 电力轨道：xpower 内嵌电力轨道 顶柜玻璃：灰玻 | G88: 整体长度：2100mm/1800mm/1500mm 整体深度：480mm 整体高度：1980mm 顶柜长度：2100mm/1800mm/1500mm 顶柜深度：300mm 顶柜高度：490mm 立体收纳长度：2100mm/1800mm/1500mm 立体收纳深度：300mm 立体收纳高度：610mm 下柜长度：2100mm/1800mm/1500mm 下柜深度：480mm 下柜高度：880mm | H88: 3501 | I88: 3261 | J88: 0.48 | K88: =IFERROR(H88,0) | L88: 0.4668 | M88: 0.2108 | N88: 0.2009 | O88: 0.1803 | P88: =IFERROR(IF(K88=0,"待填成本",ROUND(K88/(1-L88),0)),"" ) | Q88: =IFERROR(IF(K88=0,"待填成本",ROUND(K88/(1-M88),0)),"" ) | R88: =IFERROR(IF(K88=0,"待填成本",ROUND(K88/(1-N88),0)),"" ) | S88: =IFERROR(IF(K88=0,"待填成本",ROUND(K88/(1-O88),0)),"" ) | T88: =IFERROR(IF(K88=0,"",(P88-K88)/P88),"" ) | U88: =IFERROR(IF(K88=0,"",(Q88-K88)/Q88),"" ) | V88: =IFERROR(IF(K88=0,"",(R88-K88)/R88),"" ) | W88: =IFERROR(IF(K88=0,"",(S88-K88)/S88),"" ) | AC88: 19.4925 | AD88: 300 | AE88: 150
A89: 2525009040199 | B89: 餐厅-柜 | C89: 樱桃木基础餐边柜 |樱桃木AA柱餐边柜 | D89: 基础柜-下柜-1.4米 | E89: 北美进口FAS级樱桃木 | F89: 抽屉围板：实木多层板 台面：12mm岩板 背板：实木多层板（AA柱）/亚克力洞洞板 内部赠送层板：实木多层板 电力轨道：xpower 内嵌电力轨道 顶柜玻璃：灰玻 | G89: 整体长度：2100mm/1800mm/1500mm 整体深度：480mm 整体高度：1980mm 顶柜长度：2100mm/1800mm/1500mm 顶柜深度：300mm 顶柜高度：490mm 立体收纳长度：2100mm/1800mm/1500mm 立体收纳深度：300mm 立体收纳高度：610mm 下柜长度：2100mm/1800mm/1500mm 下柜深度：480mm 下柜高度：880mm | H89: 3404.3333 | I89: 3177.6667 | J89: 0.48 | K89: =IFERROR(H89,0) | L89: 0.4668 | M89: 0.2106 | N89: 0.201 | O89: 0.1805 | P89: =IFERROR(IF(K89=0,"待填成本",ROUND(K89/(1-L89),0)),"" ) | Q89: =IFERROR(IF(K89=0,"待填成本",ROUND(K89/(1-M89),0)),"" ) | R89: =IFERROR(IF(K89=0,"待填成本",ROUND(K89/(1-N89),0)),"" ) | S89: =IFERROR(IF(K89=0,"待填成本",ROUND(K89/(1-O89),0)),"" ) | T89: =IFERROR(IF(K89=0,"",(P89-K89)/P89),"" ) | U89: =IFERROR(IF(K89=0,"",(Q89-K89)/Q89),"" ) | V89: =IFERROR(IF(K89=0,"",(R89-K89)/R89),"" ) | W89: =IFERROR(IF(K89=0,"",(S89-K89)/S89),"" ) | AC89: 19.205 | AD89: 300 | AE89: 150
A90: 2525009040199 | B90: 餐厅-柜 | C90: 樱桃木基础餐边柜 |樱桃木AA柱餐边柜 | D90: 基础柜-下柜-1.3米 | E90: 北美进口FAS级樱桃木 | F90: 抽屉围板：实木多层板 台面：12mm岩板 背板：实木多层板（AA柱）/亚克力洞洞板 内部赠送层板：实木多层板 电力轨道：xpower 内嵌电力轨道 顶柜玻璃：灰玻 | G90: 整体长度：2100mm/1800mm/1500mm 整体深度：480mm 整体高度：1980mm 顶柜长度：2100mm/1800mm/1500mm 顶柜深度：300mm 顶柜高度：490mm 立体收纳长度：2100mm/1800mm/1500mm 立体收纳深度：300mm 立体收纳高度：610mm 下柜长度：2100mm/1800mm/1500mm 下柜深度：480mm 下柜高度：880mm | H90: 3307.6667 | I90: 3094.3333 | J90: 0.48 | K90: =IFERROR(H90,0) | L90: 0.4669 | M90: 0.2105 | N90: 0.2011 | O90: 0.1807 | P90: =IFERROR(IF(K90=0,"待填成本",ROUND(K90/(1-L90),0)),"" ) | Q90: =IFERROR(IF(K90=0,"待填成本",ROUND(K90/(1-M90),0)),"" ) | R90: =IFERROR(IF(K90=0,"待填成本",ROUND(K90/(1-N90),0)),"" ) | S90: =IFERROR(IF(K90=0,"待填成本",ROUND(K90/(1-O90),0)),"" ) | T90: =IFERROR(IF(K90=0,"",(P90-K90)/P90),"" ) | U90: =IFERROR(IF(K90=0,"",(Q90-K90)/Q90),"" ) | V90: =IFERROR(IF(K90=0,"",(R90-K90)/R90),"" ) | W90: =IFERROR(IF(K90=0,"",(S90-K90)/S90),"" ) | AC90: 18.9175 | AD90: 300 | AE90: 150
A91: 2525009040199 | B91: 餐厅-柜 | C91: 樱桃木基础餐边柜 |樱桃木AA柱餐边柜 | D91: 基础柜-下柜-1.2米 | E91: 北美进口FAS级樱桃木 | F91: 抽屉围板：实木多层板 台面：12mm岩板 背板：实木多层板（AA柱）/亚克力洞洞板 内部赠送层板：实木多层板 电力轨道：xpower 内嵌电力轨道 顶柜玻璃：灰玻 | G91: 整体长度：2100mm/1800mm/1500mm 整体深度：480mm 整体高度：1980mm 顶柜长度：2100mm/1800mm/1500mm 顶柜深度：300mm 顶柜高度：490mm 立体收纳长度：2100mm/1800mm/1500mm 立体收纳深度：300mm 立体收纳高度：610mm 下柜长度：2100mm/1800mm/1500mm 下柜深度：480mm 下柜高度：880mm | H91: 3211 | I91: 3011 | J91: 0.48 | K91: =IFERROR(H91,0) | L91: 0.467 | M91: 0.2103 | N91: 0.2013 | O91: 0.1809 | P91: =IFERROR(IF(K91=0,"待填成本",ROUND(K91/(1-L91),0)),"" ) | Q91: =IFERROR(IF(K91=0,"待填成本",ROUND(K91/(1-M91),0)),"" ) | R91: =IFERROR(IF(K91=0,"待填成本",ROUND(K91/(1-N91),0)),"" ) | S91: =IFERROR(IF(K91=0,"待填成本",ROUND(K91/(1-O91),0)),"" ) | T91: =IFERROR(IF(K91=0,"",(P91-K91)/P91),"" ) | U91: =IFERROR(IF(K91=0,"",(Q91-K91)/Q91),"" ) | V91: =IFERROR(IF(K91=0,"",(R91-K91)/R91),"" ) | W91: =IFERROR(IF(K91=0,"",(S91-K91)/S91),"" ) | AC91: 18.63 | AD91: 300 | AE91: 150
A92: 2525009040199 | B92: 餐厅-柜 | C92: 樱桃木基础餐边柜 |樱桃木AA柱餐边柜 | D92: 基础柜-下柜-1.1米 | E92: 北美进口FAS级樱桃木 | F92: 抽屉围板：实木多层板 台面：12mm岩板 背板：实木多层板（AA柱）/亚克力洞洞板 内部赠送层板：实木多层板 电力轨道：xpower 内嵌电力轨道 顶柜玻璃：灰玻 | G92: 整体长度：2100mm/1800mm/1500mm 整体深度：480mm 整体高度：1980mm 顶柜长度：2100mm/1800mm/1500mm 顶柜深度：300mm 顶柜高度：490mm 立体收纳长度：2100mm/1800mm/1500mm 立体收纳深度：300mm 立体收纳高度：610mm 下柜长度：2100mm/1800mm/1500mm 下柜深度：480mm 下柜高度：880mm | H92: 3114.3333 | I92: 2927.6667 | J92: 0.48 | K92: =IFERROR(H92,0) | L92: 0.4671 | M92: 0.2102 | N92: 0.2014 | O92: 0.1811 | P92: =IFERROR(IF(K92=0,"待填成本",ROUND(K92/(1-L92),0)),"" ) | Q92: =IFERROR(IF(K92=0,"待填成本",ROUND(K92/(1-M92),0)),"" ) | R92: =IFERROR(IF(K92=0,"待填成本",ROUND(K92/(1-N92),0)),"" ) | S92: =IFERROR(IF(K92=0,"待填成本",ROUND(K92/(1-O92),0)),"" ) | T92: =IFERROR(IF(K92=0,"",(P92-K92)/P92),"" ) | U92: =IFERROR(IF(K92=0,"",(Q92-K92)/Q92),"" ) | V92: =IFERROR(IF(K92=0,"",(R92-K92)/R92),"" ) | W92: =IFERROR(IF(K92=0,"",(S92-K92)/S92),"" ) | AC92: 18.3425 | AD92: 300 | AE92: 150
A93: 2525009040199 | B93: 餐厅-柜 | C93: 樱桃木基础餐边柜 |樱桃木AA柱餐边柜 | D93: 基础柜-下柜-1.0米 | E93: 北美进口FAS级樱桃木 | F93: 抽屉围板：实木多层板 台面：12mm岩板 背板：实木多层板（AA柱）/亚克力洞洞板 内部赠送层板：实木多层板 电力轨道：xpower 内嵌电力轨道 顶柜玻璃：灰玻 | G93: 整体长度：2100mm/1800mm/1500mm 整体深度：480mm 整体高度：1980mm 顶柜长度：2100mm/1800mm/1500mm 顶柜深度：300mm 顶柜高度：490mm 立体收纳长度：2100mm/1800mm/1500mm 立体收纳深度：300mm 立体收纳高度：610mm 下柜长度：2100mm/1800mm/1500mm 下柜深度：480mm 下柜高度：880mm | H93: 3017.6667 | I93: 2844.3333 | J93: 0.48 | K93: =IFERROR(H93,0) | L93: 0.4672 | M93: 0.21 | N93: 0.2016 | O93: 0.1813 | P93: =IFERROR(IF(K93=0,"待填成本",ROUND(K93/(1-L93),0)),"" ) | Q93: =IFERROR(IF(K93=0,"待填成本",ROUND(K93/(1-M93),0)),"" ) | R93: =IFERROR(IF(K93=0,"待填成本",ROUND(K93/(1-N93),0)),"" ) | S93: =IFERROR(IF(K93=0,"待填成本",ROUND(K93/(1-O93),0)),"" ) | T93: =IFERROR(IF(K93=0,"",(P93-K93)/P93),"" ) | U93: =IFERROR(IF(K93=0,"",(Q93-K93)/Q93),"" ) | V93: =IFERROR(IF(K93=0,"",(R93-K93)/R93),"" ) | W93: =IFERROR(IF(K93=0,"",(S93-K93)/S93),"" ) | AC93: 18.055 | AD93: 300 | AE93: 150
A94: 2525009040199 | B94: 餐厅-柜 | C94: 樱桃木基础餐边柜 |樱桃木AA柱餐边柜 | D94: 基础柜-整柜AA柱背板-2.1米 | E94: 北美进口FAS级樱桃木 | F94: 抽屉围板：实木多层板 台面：12mm岩板 背板：实木多层板（AA柱）/亚克力洞洞板 内部赠送层板：实木多层板 电力轨道：xpower 内嵌电力轨道 顶柜玻璃：灰玻 | G94: 整体长度：2100mm/1800mm/1500mm 整体深度：480mm 整体高度：1980mm 顶柜长度：2100mm/1800mm/1500mm 顶柜深度：300mm 顶柜高度：490mm 立体收纳长度：2100mm/1800mm/1500mm 立体收纳深度：300mm 立体收纳高度：610mm 下柜长度：2100mm/1800mm/1500mm 下柜深度：480mm 下柜高度：880mm | H94: 6422.04 | I94: 4700 | J94: 0.48 | K94: =IFERROR(H94,0) | L94: 0.4667 | M94: 0.21 | N94: 0.2 | O94: 0.1802 | P94: =IFERROR(IF(K94=0,"待填成本",ROUND(K94/(1-L94),0)),"" ) | Q94: =IFERROR(IF(K94=0,"待填成本",ROUND(K94/(1-M94),0)),"" ) | R94: =IFERROR(IF(K94=0,"待填成本",ROUND(K94/(1-N94),0)),"" ) | S94: =IFERROR(IF(K94=0,"待填成本",ROUND(K94/(1-O94),0)),"" ) | T94: =IFERROR(IF(K94=0,"",(P94-K94)/P94),"" ) | U94: =IFERROR(IF(K94=0,"",(Q94-K94)/Q94),"" ) | V94: =IFERROR(IF(K94=0,"",(R94-K94)/R94),"" ) | W94: =IFERROR(IF(K94=0,"",(S94-K94)/S94),"" ) | AA94: 19.86625 | AB94: 11.64375 | AC94: 21.2175 | AD94: 300 | AE94: 150
A95: 2525009040199 | B95: 餐厅-柜 | C95: 樱桃木基础餐边柜 |樱桃木AA柱餐边柜 | D95: 基础柜-整柜AA柱背板-2.0米 | E95: 北美进口FAS级樱桃木 | F95: 抽屉围板：实木多层板 台面：12mm岩板 背板：实木多层板（AA柱）/亚克力洞洞板 内部赠送层板：实木多层板 电力轨道：xpower 内嵌电力轨道 顶柜玻璃：灰玻 | G95: 整体长度：2100mm/1800mm/1500mm 整体深度：480mm 整体高度：1980mm 顶柜长度：2100mm/1800mm/1500mm 顶柜深度：300mm 顶柜高度：490mm 立体收纳长度：2100mm/1800mm/1500mm 立体收纳深度：300mm 立体收纳高度：610mm 下柜长度：2100mm/1800mm/1500mm 下柜深度：480mm 下柜高度：880mm | H95: 6271.7067 | I95: 4633.3333 | J95: 0.48 | K95: =IFERROR(H95,0) | L95: 0.4667 | M95: 0.2102 | N95: 0.2002 | O95: 0.1803 | P95: =IFERROR(IF(K95=0,"待填成本",ROUND(K95/(1-L95),0)),"" ) | Q95: =IFERROR(IF(K95=0,"待填成本",ROUND(K95/(1-M95),0)),"" ) | R95: =IFERROR(IF(K95=0,"待填成本",ROUND(K95/(1-N95),0)),"" ) | S95: =IFERROR(IF(K95=0,"待填成本",ROUND(K95/(1-O95),0)),"" ) | T95: =IFERROR(IF(K95=0,"",(P95-K95)/P95),"" ) | U95: =IFERROR(IF(K95=0,"",(Q95-K95)/Q95),"" ) | V95: =IFERROR(IF(K95=0,"",(R95-K95)/R95),"" ) | W95: =IFERROR(IF(K95=0,"",(S95-K95)/S95),"" ) | AA95: 19.166667 | AB95: 11.2125 | AC95: 20.93 | AD95: 300 | AE95: 150
A96: 2525009040199 | B96: 餐厅-柜 | C96: 樱桃木基础餐边柜 |樱桃木AA柱餐边柜 | D96: 基础柜-整柜AA柱背板-1.9米 | E96: 北美进口FAS级樱桃木 | F96: 抽屉围板：实木多层板 台面：12mm岩板 背板：实木多层板（AA柱）/亚克力洞洞板 内部赠送层板：实木多层板 电力轨道：xpower 内嵌电力轨道 顶柜玻璃：灰玻 | G96: 整体长度：2100mm/1800mm/1500mm 整体深度：480mm 整体高度：1980mm 顶柜长度：2100mm/1800mm/1500mm 顶柜深度：300mm 顶柜高度：490mm 立体收纳长度：2100mm/1800mm/1500mm 立体收纳深度：300mm 立体收纳高度：610mm 下柜长度：2100mm/1800mm/1500mm 下柜深度：480mm 下柜高度：880mm | H96: 6121.3733 | I96: 4566.6667 | J96: 0.48 | K96: =IFERROR(H96,0) | L96: 0.4668 | M96: 0.2103 | N96: 0.2005 | O96: 0.1803 | P96: =IFERROR(IF(K96=0,"待填成本",ROUND(K96/(1-L96),0)),"" ) | Q96: =IFERROR(IF(K96=0,"待填成本",ROUND(K96/(1-M96),0)),"" ) | R96: =IFERROR(IF(K96=0,"待填成本",ROUND(K96/(1-N96),0)),"" ) | S96: =IFERROR(IF(K96=0,"待填成本",ROUND(K96/(1-O96),0)),"" ) | T96: =IFERROR(IF(K96=0,"",(P96-K96)/P96),"" ) | U96: =IFERROR(IF(K96=0,"",(Q96-K96)/Q96),"" ) | V96: =IFERROR(IF(K96=0,"",(R96-K96)/R96),"" ) | W96: =IFERROR(IF(K96=0,"",(S96-K96)/S96),"" ) | AA96: 18.467083 | AB96: 10.78125 | AC96: 20.6425 | AD96: 300 | AE96: 150
A97: 2525009040199 | B97: 餐厅-柜 | C97: 樱桃木基础餐边柜 |樱桃木AA柱餐边柜 | D97: 基础柜-整柜AA柱背板-1.8米 | E97: 北美进口FAS级樱桃木 | F97: 抽屉围板：实木多层板 台面：12mm岩板 背板：实木多层板（AA柱）/亚克力洞洞板 内部赠送层板：实木多层板 电力轨道：xpower 内嵌电力轨道 顶柜玻璃：灰玻 | G97: 整体长度：2100mm/1800mm/1500mm 整体深度：480mm 整体高度：1980mm 顶柜长度：2100mm/1800mm/1500mm 顶柜深度：300mm 顶柜高度：490mm 立体收纳长度：2100mm/1800mm/1500mm 立体收纳深度：300mm 立体收纳高度：610mm 下柜长度：2100mm/1800mm/1500mm 下柜深度：480mm 下柜高度：880mm | H97: 5971.04 | I97: 4500 | J97: 0.48 | K97: =IFERROR(H97,0) | L97: 0.4668 | M97: 0.2105 | N97: 0.2007 | O97: 0.1804 | P97: =IFERROR(IF(K97=0,"待填成本",ROUND(K97/(1-L97),0)),"" ) | Q97: =IFERROR(IF(K97=0,"待填成本",ROUND(K97/(1-M97),0)),"" ) | R97: =IFERROR(IF(K97=0,"待填成本",ROUND(K97/(1-N97),0)),"" ) | S97: =IFERROR(IF(K97=0,"待填成本",ROUND(K97/(1-O97),0)),"" ) | T97: =IFERROR(IF(K97=0,"",(P97-K97)/P97),"" ) | U97: =IFERROR(IF(K97=0,"",(Q97-K97)/Q97),"" ) | V97: =IFERROR(IF(K97=0,"",(R97-K97)/R97),"" ) | W97: =IFERROR(IF(K97=0,"",(S97-K97)/S97),"" ) | AA97: 17.7675 | AB97: 10.35 | AC97: 20.355 | AD97: 300 | AE97: 150
...

Sheet ② 高定报价单
A1: 畔色 高定报价单 — 全新定制，逐部位填写材料和尺寸，自动出报价
A2: ↓ 填写订单基本信息后，在下方按部位逐行录入材料和尺寸，底部自动汇总出报价
A3: 客户名称 | C3: 订单日期
A4: 产品类目 | C4: 家具大小等级 | D4: 小型 / 中型 / 大型
A5: 主材 | C5: 制作件数 | D5: 1
A6: 产品名称
A7: 提示：「对应材料」填写名称后，「材料单价」会从⚙️参数设置自动查找。如未找到可手动填单价。尺寸单位：米(m)，数量为件/块/付等。
A8: 材料分类 | B8: 部位描述 | C8: 对应材料（名称与参数设置表一致） | D8: 材料单价（自动查，可手改） | E8: 长(m) | F8: 宽/高(m) | G8: 数量 | H8: 成本价（自动） | I8: 备注
D9: =IFERROR(VLOOKUP(C9,'⚙️ 参数设置'!$B:$D,3,0),"") | H9: =IFERROR(IF(OR(C9="",G9=""),0,D9*IF(E9="",1,E9)*IF(F9="",1,F9)*IF(G9="",1,G9)),0)
D10: =IFERROR(VLOOKUP(C10,'⚙️ 参数设置'!$B:$D,3,0),"") | H10: =IFERROR(IF(OR(C10="",G10=""),0,D10*IF(E10="",1,E10)*IF(F10="",1,F10)*IF(G10="",1,G10)),0)
D11: =IFERROR(VLOOKUP(C11,'⚙️ 参数设置'!$B:$D,3,0),"") | H11: =IFERROR(IF(OR(C11="",G11=""),0,D11*IF(E11="",1,E11)*IF(F11="",1,F11)*IF(G11="",1,G11)),0)
D12: =IFERROR(VLOOKUP(C12,'⚙️ 参数设置'!$B:$D,3,0),"") | H12: =IFERROR(IF(OR(C12="",G12=""),0,D12*IF(E12="",1,E12)*IF(F12="",1,F12)*IF(G12="",1,G12)),0)
D13: =IFERROR(VLOOKUP(C13,'⚙️ 参数设置'!$B:$D,3,0),"") | H13: =IFERROR(IF(OR(C13="",G13=""),0,D13*IF(E13="",1,E13)*IF(F13="",1,F13)*IF(G13="",1,G13)),0)
D14: =IFERROR(VLOOKUP(C14,'⚙️ 参数设置'!$B:$D,3,0),"") | H14: =IFERROR(IF(OR(C14="",G14=""),0,D14*IF(E14="",1,E14)*IF(F14="",1,F14)*IF(G14="",1,G14)),0)
D15: =IFERROR(VLOOKUP(C15,'⚙️ 参数设置'!$B:$D,3,0),"") | H15: =IFERROR(IF(OR(C15="",G15=""),0,D15*IF(E15="",1,E15)*IF(F15="",1,F15)*IF(G15="",1,G15)),0)
D16: =IFERROR(VLOOKUP(C16,'⚙️ 参数设置'!$B:$D,3,0),"") | H16: =IFERROR(IF(OR(C16="",G16=""),0,D16*IF(E16="",1,E16)*IF(F16="",1,F16)*IF(G16="",1,G16)),0)
D17: =IFERROR(VLOOKUP(C17,'⚙️ 参数设置'!$B:$D,3,0),"") | H17: =IFERROR(IF(OR(C17="",G17=""),0,D17*IF(E17="",1,E17)*IF(F17="",1,F17)*IF(G17="",1,G17)),0)
D18: =IFERROR(VLOOKUP(C18,'⚙️ 参数设置'!$B:$D,3,0),"") | H18: =IFERROR(IF(OR(C18="",G18=""),0,D18*IF(E18="",1,E18)*IF(F18="",1,F18)*IF(G18="",1,G18)),0)
D19: =IFERROR(VLOOKUP(C19,'⚙️ 参数设置'!$B:$D,3,0),"") | H19: =IFERROR(IF(OR(C19="",G19=""),0,D19*IF(E19="",1,E19)*IF(F19="",1,F19)*IF(G19="",1,G19)),0)
D20: =IFERROR(VLOOKUP(C20,'⚙️ 参数设置'!$B:$D,3,0),"") | H20: =IFERROR(IF(OR(C20="",G20=""),0,D20*IF(E20="",1,E20)*IF(F20="",1,F20)*IF(G20="",1,G20)),0)
... D43: =IFERROR(VLOOKUP(C43,'⚙️ 参数设置'!$B:$D,3,0),"") | H43: =IFERROR(IF(OR(C43="",G43=""),0,D43*IF(E43="",1,E43)*IF(F43="",1,F43)*IF(G43="",1,G43)),0)
E45: 厂内木材+人工成本 | H45: =SUMIF(A9:A43,"木材成本",H9:H43)+SUMIF(A9:A43,"工厂人工费用",H9:H43)
E46: 工厂利润 (系数×木材人工成本) | H46: =I45*'⚙️ 参数设置'!$H$3
E47: 工厂木作总成本 | H47: =I45+I46
E48: 配件材料成本（畔色采购） | H48: =SUMIF(A9:A43,"配件材料成本",H9:H43)
E49: 打包费 | H49: =IFERROR(VLOOKUP("打包费用-"&D4,'⚙️ 参数设置'!$B:$D,3,0)*D6,0)
E50: 运费 | H50: =IFERROR(VLOOKUP("运费-"&D4,'⚙️ 参数设置'!$B:$D,3,0)*D6,0)
E51: 安装费 | H51: =IFERROR(VLOOKUP("上门安装费-"&D4,'⚙️ 参数设置'!$B:$D,3,0)*D6,0)
E52: 畔色总成本 | H52: =I47+I48+I49+I50+I51
E54: 高定最终报价（含15%利润） | H54: =ROUND(I52/(1-'⚙️ 参数设置'!$H$4),0)
